Workbook

Sheet thongke
A1: Tháng | B1: Giới tính | D1: Tổng cộng | E1: Số người cần xét nghiệm đường máu mao mạch | G1: Tổng cộng | H1: Số nghi ngờ ĐTĐ thông qua tầm soát | J1: Tổng cộng | K1: Số nghi ngờ THA thông qua tầm soát | M1: Tổng cộng | N1: Nguy cơ mắc Hen | P1: Tổng cộng | Q1: Nguy cơ mắc COPD | S1: Tổng cộng
B2: Nam | C2: Nữ | E2: Nam | F2: Nữ | H2: Nam | I2: Nữ | K2: Nam | L2: Nữ | N2: Nam | O2: Nữ | Q2: Nam | R2: Nữ
A3: Tháng 1 | B3: =COUNTIFS('ksl2'!$AM:$AM,$A3,'ksl2'!$B:$B,$B$2) -> 55 | C3: =COUNTIFS('ksl2'!$AM:$AM,$A3,'ksl2'!$B:$B,$C$2) -> 95 | D3: =SUM(B3:C3) -> 150 | E3: =COUNTIFS('ksl2'!$AM:$AM,$A3,'ksl2'!$B:$B,$E$2,'ksl2'!$AH:$AH,"Có") -> 46 | F3: =COUNTIFS('ksl2'!$AM:$AM,$A3,'ksl2'!$B:$B,$F$2,'ksl2'!$AH:$AH,"Có") -> 68 | G3: =SUM(E3:F3) -> 114 | H3: =COUNTIFS('ksl2'!$AM:$AM,$A3,'ksl2'!$B:$B,$H$2,'ksl2'!$AI:$AI,"Có") -> 46 | I3: =COUNTIFS('ksl2'!$AM:$AM,$A3,'ksl2'!$B:$B,$I$2,'ksl2'!$AI:$AI,"Có") -> 68 | J3: =SUM(H3:I3) -> 114 | K3: =COUNTIFS('ksl2'!$AM:$AM,$A3,'ksl2'!$B:$B,$K$2,'ksl2'!$AJ:$AJ,"Có") -> 22 | L3: =COUNTIFS('ksl2'!$AM:$AM,$A3,'ksl2'!$B:$B,$L$2,'ksl2'!$AJ:$AJ,"Có") -> 24 | M3: =SUM(K3:L3) -> 46 | N3: =COUNTIFS('ksl2'!$AM:$AM,$A3,'ksl2'!$B:$B,$N$2,'ksl2'!$AF:$AF,"Có") -> 0 | O3: =COUNTIFS('ksl2'!$AM:$AM,$A3,'ksl2'!$B:$B,$O$2,'ksl2'!$AF:$AF,"Có") -> 0 | P3: =SUM(N3:O3) -> 0 | Q3: =COUNTIFS('ksl2'!$AM:$AM,$A3,'ksl2'!$B:$B,$Q$2,'ksl2'!$AG:$AG,"Có") -> 0 | R3: =COUNTIFS('ksl2'!$AM:$AM,$A3,'ksl2'!$B:$B,$R$2,'ksl2'!$AG:$AG,"Có") -> 0 | S3: =SUM(Q3:R3) -> 0
A4: Tháng 2 | B4: =COUNTIFS('ksl2'!$AM:$AM,$A4,'ksl2'!$B:$B,$B$2) -> 95 | C4: =COUNTIFS('ksl2'!$AM:$AM,$A4,'ksl2'!$B:$B,$C$2) -> 105 | D4: =SUM(B4:C4) -> 200 | E4: =COUNTIFS('ksl2'!$AM:$AM,$A4,'ksl2'!$B:$B,$E$2,'ksl2'!$AH:$AH,"Có") -> 83 | F4: =COUNTIFS('ksl2'!$AM:$AM,$A4,'ksl2'!$B:$B,$F$2,'ksl2'!$AH:$AH,"Có") -> 62 | G4: =SUM(E4:F4) -> 145 | H4: =COUNTIFS('ksl2'!$AM:$AM,$A4,'ksl2'!$B:$B,$H$2,'ksl2'!$AI:$AI,"Có") -> 83 | I4: =COUNTIFS('ksl2'!$AM:$AM,$A4,'ksl2'!$B:$B,$I$2,'ksl2'!$AI:$AI,"Có") -> 62 | J4: =SUM(H4:I4) -> 145 | K4: =COUNTIFS('ksl2'!$AM:$AM,$A4,'ksl2'!$B:$B,$K$2,'ksl2'!$AJ:$AJ,"Có") -> 36 | L4: =COUNTIFS('ksl2'!$AM:$AM,$A4,'ksl2'!$B:$B,$L$2,'ksl2'!$AJ:$AJ,"Có") -> 29 | M4: =SUM(K4:L4) -> 65 | N4: =COUNTIFS('ksl2'!$AM:$AM,$A4,'ksl2'!$B:$B,$N$2,'ksl2'!$AF:$AF,"Có") -> 0 | O4: =COUNTIFS('ksl2'!$AM:$AM,$A4,'ksl2'!$B:$B,$O$2,'ksl2'!$AF:$AF,"Có") -> 0 | P4: =SUM(N4:O4) -> 0 | Q4: =COUNTIFS('ksl2'!$AM:$AM,$A4,'ksl2'!$B:$B,$Q$2,'ksl2'!$AG:$AG,"Có") -> 0 | R4: =COUNTIFS('ksl2'!$AM:$AM,$A4,'ksl2'!$B:$B,$R$2,'ksl2'!$AG:$AG,"Có") -> 0 | S4: =SUM(Q4:R4) -> 0
A5: Tháng 3 | B5: =COUNTIFS('ksl2'!$AM:$AM,$A5,'ksl2'!$B:$B,$B$2) -> 78 | C5: =COUNTIFS('ksl2'!$AM:$AM,$A5,'ksl2'!$B:$B,$C$2) -> 122 | D5: =SUM(B5:C5) -> 200 | E5: =COUNTIFS('ksl2'!$AM:$AM,$A5,'ksl2'!$B:$B,$E$2,'ksl2'!$AH:$AH,"Có") -> 61 | F5: =COUNTIFS('ksl2'!$AM:$AM,$A5,'ksl2'!$B:$B,$F$2,'ksl2'!$AH:$AH,"Có") -> 76 | G5: =SUM(E5:F5) -> 137 | H5: =COUNTIFS('ksl2'!$AM:$AM,$A5,'ksl2'!$B:$B,$H$2,'ksl2'!$AI:$AI,"Có") -> 61 | I5: =COUNTIFS('ksl2'!$AM:$AM,$A5,'ksl2'!$B:$B,$I$2,'ksl2'!$AI:$AI,"Có") -> 76 | J5: =SUM(H5:I5) -> 137 | K5: =COUNTIFS('ksl2'!$AM:$AM,$A5,'ksl2'!$B:$B,$K$2,'ksl2'!$AJ:$AJ,"Có") -> 25 | L5: =COUNTIFS('ksl2'!$AM:$AM,$A5,'ksl2'!$B:$B,$L$2,'ksl2'!$AJ:$AJ,"Có") -> 37 | M5: =SUM(K5:L5) -> 62 | N5: =COUNTIFS('ksl2'!$AM:$AM,$A5,'ksl2'!$B:$B,$N$2,'ksl2'!$AF:$AF,"Có") -> 0 | O5: =COUNTIFS('ksl2'!$AM:$AM,$A5,'ksl2'!$B:$B,$O$2,'ksl2'!$AF:$AF,"Có") -> 0 | P5: =SUM(N5:O5) -> 0 | Q5: =COUNTIFS('ksl2'!$AM:$AM,$A5,'ksl2'!$B:$B,$Q$2,'ksl2'!$AG:$AG,"Có") -> 0 | R5: =COUNTIFS('ksl2'!$AM:$AM,$A5,'ksl2'!$B:$B,$R$2,'ksl2'!$AG:$AG,"Có") -> 0 | S5: =SUM(Q5:R5) -> 0
A6: Tháng 4 | B6: =COUNTIFS('ksl2'!$AM:$AM,$A6,'ksl2'!$B:$B,$B$2) -> 156 | C6: =COUNTIFS('ksl2'!$AM:$AM,$A6,'ksl2'!$B:$B,$C$2) -> 244 | D6: =SUM(B6:C6) -> 400 | E6: =COUNTIFS('ksl2'!$AM:$AM,$A6,'ksl2'!$B:$B,$E$2,'ksl2'!$AH:$AH,"Có") -> 140 | F6: =COUNTIFS('ksl2'!$AM:$AM,$A6,'ksl2'!$B:$B,$F$2,'ksl2'!$AH:$AH,"Có") -> 153 | G6: =SUM(E6:F6) -> 293 | H6: =COUNTIFS('ksl2'!$AM:$AM,$A6,'ksl2'!$B:$B,$H$2,'ksl2'!$AI:$AI,"Có") -> 140 | I6: =COUNTIFS('ksl2'!$AM:$AM,$A6,'ksl2'!$B:$B,$I$2,'ksl2'!$AI:$AI,"Có") -> 153 | J6: =SUM(H6:I6) -> 293 | K6: =COUNTIFS('ksl2'!$AM:$AM,$A6,'ksl2'!$B:$B,$K$2,'ksl2'!$AJ:$AJ,"Có") -> 44 | L6: =COUNTIFS('ksl2'!$AM:$AM,$A6,'ksl2'!$B:$B,$L$2,'ksl2'!$AJ:$AJ,"Có") -> 77 | M6: =SUM(K6:L6) -> 121 | N6: =COUNTIFS('ksl2'!$AM:$AM,$A6,'ksl2'!$B:$B,$N$2,'ksl2'!$AF:$AF,"Có") -> 0 | O6: =COUNTIFS('ksl2'!$AM:$AM,$A6,'ksl2'!$B:$B,$O$2,'ksl2'!$AF:$AF,"Có") -> 0 | P6: =SUM(N6:O6) -> 0 | Q6: =COUNTIFS('ksl2'!$AM:$AM,$A6,'ksl2'!$B:$B,$Q$2,'ksl2'!$AG:$AG,"Có") -> 0 | R6: =COUNTIFS('ksl2'!$AM:$AM,$A6,'ksl2'!$B:$B,$R$2,'ksl2'!$AG:$AG,"Có") -> 0 | S6: =SUM(Q6:R6) -> 0
A7: Tháng 5 | B7: =COUNTIFS('ksl2'!$AM:$AM,$A7,'ksl2'!$B:$B,$B$2) -> 119 | C7: =COUNTIFS('ksl2'!$AM:$AM,$A7,'ksl2'!$B:$B,$C$2) -> 191 | D7: =SUM(B7:C7) -> 310 | E7: =COUNTIFS('ksl2'!$AM:$AM,$A7,'ksl2'!$B:$B,$E$2,'ksl2'!$AH:$AH,"Có") -> 108 | F7: =COUNTIFS('ksl2'!$AM:$AM,$A7,'ksl2'!$B:$B,$F$2,'ksl2'!$AH:$AH,"Có") -> 136 | G7: =SUM(E7:F7) -> 244 | H7: =COUNTIFS('ksl2'!$AM:$AM,$A7,'ksl2'!$B:$B,$H$2,'ksl2'!$AI:$AI,"Có") -> 108 | I7: =COUNTIFS('ksl2'!$AM:$AM,$A7,'ksl2'!$B:$B,$I$2,'ksl2'!$AI:$AI,"Có") -> 136 | J7: =SUM(H7:I7) -> 244 | K7: =COUNTIFS('ksl2'!$AM:$AM,$A7,'ksl2'!$B:$B,$K$2,'ksl2'!$AJ:$AJ,"Có") -> 34 | L7: =COUNTIFS('ksl2'!$AM:$AM,$A7,'ksl2'!$B:$B,$L$2,'ksl2'!$AJ:$AJ,"Có") -> 57 | M7: =SUM(K7:L7) -> 91 | N7: =COUNTIFS('ksl2'!$AM:$AM,$A7,'ksl2'!$B:$B,$N$2,'ksl2'!$AF:$AF,"Có") -> 0 | O7: =COUNTIFS('ksl2'!$AM:$AM,$A7,'ksl2'!$B:$B,$O$2,'ksl2'!$AF:$AF,"Có") -> 0 | P7: =SUM(N7:O7) -> 0 | Q7: =COUNTIFS('ksl2'!$AM:$AM,$A7,'ksl2'!$B:$B,$Q$2,'ksl2'!$AG:$AG,"Có") -> 0 | R7: =COUNTIFS('ksl2'!$AM:$AM,$A7,'ksl2'!$B:$B,$R$2,'ksl2'!$AG:$AG,"Có") -> 0 | S7: =SUM(Q7:R7) -> 0
A8: Tháng 6 | B8: =COUNTIFS('ksl2'!$AM:$AM,$A8,'ksl2'!$B:$B,$B$2) -> 0 | C8: =COUNTIFS('ksl2'!$AM:$AM,$A8,'ksl2'!$B:$B,$C$2) -> 0 | D8: =SUM(B8:C8) -> 0 | E8: =COUNTIFS('ksl2'!$AM:$AM,$A8,'ksl2'!$B:$B,$E$2,'ksl2'!$AH:$AH,"Có") -> 0 | F8: =COUNTIFS('ksl2'!$AM:$AM,$A8,'ksl2'!$B:$B,$F$2,'ksl2'!$AH:$AH,"Có") -> 0 | G8: =SUM(E8:F8) -> 0 | H8: =COUNTIFS('ksl2'!$AM:$AM,$A8,'ksl2'!$B:$B,$H$2,'ksl2'!$AI:$AI,"Có") -> 0 | I8: =COUNTIFS('ksl2'!$AM:$AM,$A8,'ksl2'!$B:$B,$I$2,'ksl2'!$AI:$AI,"Có") -> 0 | J8: =SUM(H8:I8) -> 0 | K8: =COUNTIFS('ksl2'!$AM:$AM,$A8,'ksl2'!$B:$B,$K$2,'ksl2'!$AJ:$AJ,"Có") -> 0 | L8: =COUNTIFS('ksl2'!$AM:$AM,$A8,'ksl2'!$B:$B,$L$2,'ksl2'!$AJ:$AJ,"Có") -> 0 | M8: =SUM(K8:L8) -> 0 | N8: =COUNTIFS('ksl2'!$AM:$AM,$A8,'ksl2'!$B:$B,$N$2,'ksl2'!$AF:$AF,"Có") -> 0 | O8: =COUNTIFS('ksl2'!$AM:$AM,$A8,'ksl2'!$B:$B,$O$2,'ksl2'!$AF:$AF,"Có") -> 0 | P8: =SUM(N8:O8) -> 0 | Q8: =COUNTIFS('ksl2'!$AM:$AM,$A8,'ksl2'!$B:$B,$Q$2,'ksl2'!$AG:$AG,"Có") -> 0 | R8: =COUNTIFS('ksl2'!$AM:$AM,$A8,'ksl2'!$B:$B,$R$2,'ksl2'!$AG:$AG,"Có") -> 0 | S8: =SUM(Q8:R8) -> 0
A9: Tháng 7 | B9: =COUNTIFS('ksl2'!$AM:$AM,$A9,'ksl2'!$B:$B,$B$2) -> 0 | C9: =COUNTIFS('ksl2'!$AM:$AM,$A9,'ksl2'!$B:$B,$C$2) -> 0 | D9: =SUM(B9:C9) -> 0 | E9: =COUNTIFS('ksl2'!$AM:$AM,$A9,'ksl2'!$B:$B,$E$2,'ksl2'!$AH:$AH,"Có") -> 0 | F9: =COUNTIFS('ksl2'!$AM:$AM,$A9,'ksl2'!$B:$B,$F$2,'ksl2'!$AH:$AH,"Có") -> 0 | G9: =SUM(E9:F9) -> 0 | H9: =COUNTIFS('ksl2'!$AM:$AM,$A9,'ksl2'!$B:$B,$H$2,'ksl2'!$AI:$AI,"Có") -> 0 | I9: =COUNTIFS('ksl2'!$AM:$AM,$A9,'ksl2'!$B:$B,$I$2,'ksl2'!$AI:$AI,"Có") -> 0 | J9: =SUM(H9:I9) -> 0 | K9: =COUNTIFS('ksl2'!$AM:$AM,$A9,'ksl2'!$B:$B,$K$2,'ksl2'!$AJ:$AJ,"Có") -> 0 | L9: =COUNTIFS('ksl2'!$AM:$AM,$A9,'ksl2'!$B:$B,$L$2,'ksl2'!$AJ:$AJ,"Có") -> 0 | M9: =SUM(K9:L9) -> 0 | N9: =COUNTIFS('ksl2'!$AM:$AM,$A9,'ksl2'!$B:$B,$N$2,'ksl2'!$AF:$AF,"Có") -> 0 | O9: =COUNTIFS('ksl2'!$AM:$AM,$A9,'ksl2'!$B:$B,$O$2,'ksl2'!$AF:$AF,"Có") -> 0 | P9: =SUM(N9:O9) -> 0 | Q9: =COUNTIFS('ksl2'!$AM:$AM,$A9,'ksl2'!$B:$B,$Q$2,'ksl2'!$AG:$AG,"Có") -> 0 | R9: =COUNTIFS('ksl2'!$AM:$AM,$A9,'ksl2'!$B:$B,$R$2,'ksl2'!$AG:$AG,"Có") -> 0 | S9: =SUM(Q9:R9) -> 0
A10: Tháng 8 | B10: =COUNTIFS('ksl2'!$AM:$AM,$A10,'ksl2'!$B:$B,$B$2) -> 0 | C10: =COUNTIFS('ksl2'!$AM:$AM,$A10,'ksl2'!$B:$B,$C$2) -> 0 | D10: =SUM(B10:C10) -> 0 | E10: =COUNTIFS('ksl2'!$AM:$AM,$A10,'ksl2'!$B:$B,$E$2,'ksl2'!$AH:$AH,"Có") -> 0 | F10: =COUNTIFS('ksl2'!$AM:$AM,$A10,'ksl2'!$B:$B,$F$2,'ksl2'!$AH:$AH,"Có") -> 0 | G10: =SUM(E10:F10) -> 0 | H10: =COUNTIFS('ksl2'!$AM:$AM,$A10,'ksl2'!$B:$B,$H$2,'ksl2'!$AI:$AI,"Có") -> 0 | I10: =COUNTIFS('ksl2'!$AM:$AM,$A10,'ksl2'!$B:$B,$I$2,'ksl2'!$AI:$AI,"Có") -> 0 | J10: =SUM(H10:I10) -> 0 | K10: =COUNTIFS('ksl2'!$AM:$AM,$A10,'ksl2'!$B:$B,$K$2,'ksl2'!$AJ:$AJ,"Có") -> 0 | L10: =COUNTIFS('ksl2'!$AM:$AM,$A10,'ksl2'!$B:$B,$L$2,'ksl2'!$AJ:$AJ,"Có") -> 0 | M10: =SUM(K10:L10) -> 0 | N10: =COUNTIFS('ksl2'!$AM:$AM,$A10,'ksl2'!$B:$B,$N$2,'ksl2'!$AF:$AF,"Có") -> 0 | O10: =COUNTIFS('ksl2'!$AM:$AM,$A10,'ksl2'!$B:$B,$O$2,'ksl2'!$AF:$AF,"Có") -> 0 | P10: =SUM(N10:O10) -> 0 | Q10: =COUNTIFS('ksl2'!$AM:$AM,$A10,'ksl2'!$B:$B,$Q$2,'ksl2'!$AG:$AG,"Có") -> 0 | R10: =COUNTIFS('ksl2'!$AM:$AM,$A10,'ksl2'!$B:$B,$R$2,'ksl2'!$AG:$AG,"Có") -> 0 | S10: =SUM(Q10:R10) -> 0
A11: Tháng 9 | B11: =COUNTIFS('ksl2'!$AM:$AM,$A11,'ksl2'!$B:$B,$B$2) -> 0 | C11: =COUNTIFS('ksl2'!$AM:$AM,$A11,'ksl2'!$B:$B,$C$2) -> 0 | D11: =SUM(B11:C11) -> 0 | E11: =COUNTIFS('ksl2'!$AM:$AM,$A11,'ksl2'!$B:$B,$E$2,'ksl2'!$AH:$AH,"Có") -> 0 | F11: =COUNTIFS('ksl2'!$AM:$AM,$A11,'ksl2'!$B:$B,$F$2,'ksl2'!$AH:$AH,"Có") -> 0 | G11: =SUM(E11:F11) -> 0 | H11: =COUNTIFS('ksl2'!$AM:$AM,$A11,'ksl2'!$B:$B,$H$2,'ksl2'!$AI:$AI,"Có") -> 0 | I11: =COUNTIFS('ksl2'!$AM:$AM,$A11,'ksl2'!$B:$B,$I$2,'ksl2'!$AI:$AI,"Có") -> 0 | J11: =SUM(H11:I11) -> 0 | K11: =COUNTIFS('ksl2'!$AM:$AM,$A11,'ksl2'!$B:$B,$K$2,'ksl2'!$AJ:$AJ,"Có") -> 0 | L11: =COUNTIFS('ksl2'!$AM:$AM,$A11,'ksl2'!$B:$B,$L$2,'ksl2'!$AJ:$AJ,"Có") -> 0 | M11: =SUM(K11:L11) -> 0 | N11: =COUNTIFS('ksl2'!$AM:$AM,$A11,'ksl2'!$B:$B,$N$2,'ksl2'!$AF:$AF,"Có") -> 0 | O11: =COUNTIFS('ksl2'!$AM:$AM,$A11,'ksl2'!$B:$B,$O$2,'ksl2'!$AF:$AF,"Có") -> 0 | P11: =SUM(N11:O11) -> 0 | Q11: =COUNTIFS('ksl2'!$AM:$AM,$A11,'ksl2'!$B:$B,$Q$2,'ksl2'!$AG:$AG,"Có") -> 0 | R11: =COUNTIFS('ksl2'!$AM:$AM,$A11,'ksl2'!$B:$B,$R$2,'ksl2'!$AG:$AG,"Có") -> 0 | S11: =SUM(Q11:R11) -> 0
A12: Tháng 10 | B12: =COUNTIFS('ksl2'!$AM:$AM,$A12,'ksl2'!$B:$B,$B$2) -> 0 | C12: =COUNTIFS('ksl2'!$AM:$AM,$A12,'ksl2'!$B:$B,$C$2) -> 0 | D12: =SUM(B12:C12) -> 0 | E12: =COUNTIFS('ksl2'!$AM:$AM,$A12,'ksl2'!$B:$B,$E$2,'ksl2'!$AH:$AH,"Có") -> 0 | F12: =COUNTIFS('ksl2'!$AM:$AM,$A12,'ksl2'!$B:$B,$F$2,'ksl2'!$AH:$AH,"Có") -> 0 | G12: =SUM(E12:F12) -> 0 | H12: =COUNTIFS('ksl2'!$AM:$AM,$A12,'ksl2'!$B:$B,$H$2,'ksl2'!$AI:$AI,"Có") -> 0 | I12: =COUNTIFS('ksl2'!$AM:$AM,$A12,'ksl2'!$B:$B,$I$2,'ksl2'!$AI:$AI,"Có") -> 0 | J12: =SUM(H12:I12) -> 0 | K12: =COUNTIFS('ksl2'!$AM:$AM,$A12,'ksl2'!$B:$B,$K$2,'ksl2'!$AJ:$AJ,"Có") -> 0 | L12: =COUNTIFS('ksl2'!$AM:$AM,$A12,'ksl2'!$B:$B,$L$2,'ksl2'!$AJ:$AJ,"Có") -> 0 | M12: =SUM(K12:L12) -> 0 | N12: =COUNTIFS('ksl2'!$AM:$AM,$A12,'ksl2'!$B:$B,$N$2,'ksl2'!$AF:$AF,"Có") -> 0 | O12: =COUNTIFS('ksl2'!$AM:$AM,$A12,'ksl2'!$B:$B,$O$2,'ksl2'!$AF:$AF,"Có") -> 0 | P12: =SUM(N12:O12) -> 0 | Q12: =COUNTIFS('ksl2'!$AM:$AM,$A12,'ksl2'!$B:$B,$Q$2,'ksl2'!$AG:$AG,"Có") -> 0 | R12: =COUNTIFS('ksl2'!$AM:$AM,$A12,'ksl2'!$B:$B,$R$2,'ksl2'!$AG:$AG,"Có") -> 0 | S12: =SUM(Q12:R12) -> 0
A13: Tháng 11 | B13: =COUNTIFS('ksl2'!$AM:$AM,$A13,'ksl2'!$B:$B,$B$2) -> 0 | C13: =COUNTIFS('ksl2'!$AM:$AM,$A13,'ksl2'!$B:$B,$C$2) -> 0 | D13: =SUM(B13:C13) -> 0 | E13: =COUNTIFS('ksl2'!$AM:$AM,$A13,'ksl2'!$B:$B,$E$2,'ksl2'!$AH:$AH,"Có") -> 0 | F13: =COUNTIFS('ksl2'!$AM:$AM,$A13,'ksl2'!$B:$B,$F$2,'ksl2'!$AH:$AH,"Có") -> 0 | G13: =SUM(E13:F13) -> 0 | H13: =COUNTIFS('ksl2'!$AM:$AM,$A13,'ksl2'!$B:$B,$H$2,'ksl2'!$AI:$AI,"Có") -> 0 | I13: =COUNTIFS('ksl2'!$AM:$AM,$A13,'ksl2'!$B:$B,$I$2,'ksl2'!$AI:$AI,"Có") -> 0 | J13: =SUM(H13:I13) -> 0 | K13: =COUNTIFS('ksl2'!$AM:$AM,$A13,'ksl2'!$B:$B,$K$2,'ksl2'!$AJ:$AJ,"Có") -> 0 | L13: =COUNTIFS('ksl2'!$AM:$AM,$A13,'ksl2'!$B:$B,$L$2,'ksl2'!$AJ:$AJ,"Có") -> 0 | M13: =SUM(K13:L13) -> 0 | N13: =COUNTIFS('ksl2'!$AM:$AM,$A13,'ksl2'!$B:$B,$N$2,'ksl2'!$AF:$AF,"Có") -> 0 | O13: =COUNTIFS('ksl2'!$AM:$AM,$A13,'ksl2'!$B:$B,$O$2,'ksl2'!$AF:$AF,"Có") -> 0 | P13: =SUM(N13:O13) -> 0 | Q13: =COUNTIFS('ksl2'!$AM:$AM,$A13,'ksl2'!$B:$B,$Q$2,'ksl2'!$AG:$AG,"Có") -> 0 | R13: =COUNTIFS('ksl2'!$AM:$AM,$A13,'ksl2'!$B:$B,$R$2,'ksl2'!$AG:$AG,"Có") -> 0 | S13: =SUM(Q13:R13) -> 0
A14: Tháng 12 | B14: =COUNTIFS('ksl2'!$AM:$AM,$A14,'ksl2'!$B:$B,$B$2) -> 0 | C14: =COUNTIFS('ksl2'!$AM:$AM,$A14,'ksl2'!$B:$B,$C$2) -> 0 | D14: =SUM(B14:C14) -> 0 | E14: =COUNTIFS('ksl2'!$AM:$AM,$A14,'ksl2'!$B:$B,$E$2,'ksl2'!$AH:$AH,"Có") -> 0 | F14: =COUNTIFS('ksl2'!$AM:$AM,$A14,'ksl2'!$B:$B,$F$2,'ksl2'!$AH:$AH,"Có") -> 0 | G14: =SUM(E14:F14) -> 0 | H14: =COUNTIFS('ksl2'!$AM:$AM,$A14,'ksl2'!$B:$B,$H$2,'ksl2'!$AI:$AI,"Có") -> 0 | I14: =COUNTIFS('ksl2'!$AM:$AM,$A14,'ksl2'!$B:$B,$I$2,'ksl2'!$AI:$AI,"Có") -> 0 | J14: =SUM(H14:I14) -> 0 | K14: =COUNTIFS('ksl2'!$AM:$AM,$A14,'ksl2'!$B:$B,$K$2,'ksl2'!$AJ:$AJ,"Có") -> 0 | L14: =COUNTIFS('ksl2'!$AM:$AM,$A14,'ksl2'!$B:$B,$L$2,'ksl2'!$AJ:$AJ,"Có") -> 0 | M14: =SUM(K14:L14) -> 0 | N14: =COUNTIFS('ksl2'!$AM:$AM,$A14,'ksl2'!$B:$B,$N$2,'ksl2'!$AF:$AF,"Có") -> 0 | O14: =COUNTIFS('ksl2'!$AM:$AM,$A14,'ksl2'!$B:$B,$O$2,'ksl2'!$AF:$AF,"Có") -> 0 | P14: =SUM(N14:O14) -> 0 | Q14: =COUNTIFS('ksl2'!$AM:$AM,$A14,'ksl2'!$B:$B,$Q$2,'ksl2'!$AG:$AG,"Có") -> 0 | R14: =COUNTIFS('ksl2'!$AM:$AM,$A14,'ksl2'!$B:$B,$R$2,'ksl2'!$AG:$AG,"Có") -> 0 | S14: =SUM(Q14:R14) -> 0
A15: Tổng cộng | B15: =SUM(B3:B14) -> 503 | C15: =SUM(C3:C14) -> 757 | D15: =SUM(D3:D14) -> 1260 | E15: =SUM(E3:E14) -> 438 | F15: =SUM(F3:F14) -> 495 | G15: =SUM(G3:G14) -> 933 | H15: =SUM(H3:H14) -> 438 | I15: =SUM(I3:I14) -> 495 | ... S15: =SUM(S3:S14) -> 0
B16: Giới tính | E16: Số người cần xét nghiệm đường máu mao mạch | H16: Số nghi ngờ ĐTĐ thông qua tầm soát | K16: Số nghi ngờ THA thông qua tầm soát | N16: Nguy cơ mắc Hen | Q16: Nguy cơ mắc COPD

Sheet ksl2
A1: Họ tên (*) | B1: Giới tính (*) | C1: Năm sinh (*) | D1: Tuổi (Tự động) | E1: Gia đình mắc ĐTD | F1: Chiều cao | G1: Cân nặng | H1: BMI (Tự động) | I1: Vòng eo | J1: HA tâm thu (*) | K1: HA tâm trương (*) | L1: Điểm Giới tính (Tự động) | M1: Điểm Tuổi (Tự động) | N1: Điểm Gia đình (Tự động) | O1: Điểm BMI (Tự động) | P1: Điểm Vòng eo (Tự động) | Q1: Điểm Huyết áp (Tự động) | R1: Tổng điểm (Tự động) | S1: Câu hỏi tầm soát Hen (GINA) | AA1: Câu hỏi tầm soát bệnh Phổi tắc nghẽn mãn tính (GOLD) | AF1: Nguy cơ mắc HEN (Tự động) | AG1: Nguy cơ mắc COPD (Tự động) | AH1: Cần xét nghiệm đường máu mao mạch (Tự động) | AI1: Nguy cơ Đái tháo đường (Tự động) | AJ1: Nghi ngờ Tăng huyết áp (Tự động) | AK1: Địa chỉ | AL1: Ngày khám (*) | AM1: Tháng (Tự động) | AN1: Khóm (Tự động)
S2: 1 | T2: 2 | U2: 3 | V2: 4 | W2: 5 | X2: 6 | Y2: 7 | Z2: 8 | AA2: 1 | AB2: 2 | AC2: 3 | AD2: 4 | AE2: 5
A3: Column1 | B3: Column2 | C3: Column3 | D3: Column4 | E3: Column5 | F3: Column6 | G3: Column7 | H3: Column8 | I3: Column9 | J3: Column10 | K3: Column11 | L3: Column12 | M3: Column13 | N3: Column14 | O3: Column15 | P3: Column16 | Q3: Column17 | R3: Column18 | S3: Column19 | T3: Column20 | U3: Column21 | V3: Column22 | W3: Column23 | X3: Column24 | Y3: Column25 | Z3: Column26 | AA3: Column27 | AB3: Column28 | AC3: Column29 | AD3: Column30 | AE3: Column31 | AF3: Column32 | AG3: Column33 | AH3: Column34 | AI3: Column35 | AJ3: Column36 | AK3: Column37 | AL3: Column38 | AM3: Column39 | AN3: Column40
A4: TRẦN THỊ CHIẾN | B4: Nữ | C4: 01/01/1960 | D4: =DATEDIF(C4,TODAY(),"Y") -> 66 | E4: Không | F4: 160 | G4: 55 | H4: =G4/((F4/100)*(F4/100)) -> 21.484375 | I4: 68 | J4: 120 | K4: 70 | L4: =IF(B4="Nữ",0,2) -> 0 | M4: =IF(D4<45,0,IF(D4<=49,1,2)) -> 2 | N4: =IF(E4="Có",4,0) -> 0 | O4: =IF(H4<23,0,IF(H4<27.5,3,5)) -> 0 | P4: =IF(OR(AND(B4="Nam",I4>=90),AND(B4="Nữ",I4>=80)),2,0) -> 0 | Q4: =IF(OR(J4>=140,K4>=90),2,0) -> 0 | R4: =SUM(L4:Q4) -> 2 | AD4: x | AF4: =IF(COUNTIF(S4:Z4,"X")>=2,"Có","Không") -> Không | AG4: =IF(COUNTIF(AA4:AE4,"X")>=3,"Có","Không") -> Không | AH4: =IF((R4)>=6,"Có","Không") -> Không | AI4: =IF((R4)>=6,"Có","Không") -> Không | AJ4: =IF(OR(J4>=140,K4>=90),"Có","Không") -> Không | AK4: Phường Hiệp Thành, tỉnh Cà Mau | AL4: 46053 | AM4: ="Tháng "&MONTH(AL4) -> Tháng 1 | AN4: =LEFT(AK4,FIND(",",AK4)-1) -> Phường Hiệp Thành
A5: NGUYỄN THỊ ĐÀO | B5: Nữ | C5: 01/01/1969 | D5: =DATEDIF(C5,TODAY(),"Y") -> 57 | E5: Không | F5: 155 | G5: 66 | H5: =G5/((F5/100)*(F5/100)) -> 27.471384 | I5: 86 | J5: 120 | K5: 70 | L5: =IF(B5="Nữ",0,2) -> 0 | M5: =IF(D5<45,0,IF(D5<=49,1,2)) -> 2 | N5: =IF(E5="Có",4,0) -> 0 | O5: =IF(H5<23,0,IF(H5<27.5,3,5)) -> 3 | P5: =IF(OR(AND(B5="Nam",I5>=90),AND(B5="Nữ",I5>=80)),2,0) -> 2 | Q5: =IF(OR(J5>=140,K5>=90),2,0) -> 0 | R5: =SUM(L5:Q5) -> 7 | AD5: x | AF5: =IF(COUNTIF(S5:Z5,"X")>=2,"Có","Không") -> Không | AG5: =IF(COUNTIF(AA5:AE5,"X")>=3,"Có","Không") -> Không | AH5: =IF((R5)>=6,"Có","Không") -> Có | AI5: =IF((R5)>=6,"Có","Không") -> Có | AJ5: =IF(OR(J5>=140,K5>=90),"Có","Không") -> Không | AK5: Phường Hiệp Thành, tỉnh Cà Mau | AL5: 46053 | AM5: ="Tháng "&MONTH(AL5) -> Tháng 1 | AN5: =LEFT(AK5,FIND(",",AK5)-1) -> Phường Hiệp Thành
A6: THẠCH SI RA | B6: Nam | C6: 01/01/1974 | D6: =DATEDIF(C6,TODAY(),"Y") -> 52 | E6: Không | F6: 158 | G6: 58 | H6: =G6/((F6/100)*(F6/100)) -> 23.233456 | I6: 97 | J6: 140 | K6: 80 | L6: =IF(B6="Nữ",0,2) -> 2 | M6: =IF(D6<45,0,IF(D6<=49,1,2)) -> 2 | N6: =IF(E6="Có",4,0) -> 0 | O6: =IF(H6<23,0,IF(H6<27.5,3,5)) -> 3 | P6: =IF(OR(AND(B6="Nam",I6>=90),AND(B6="Nữ",I6>=80)),2,0) -> 2 | Q6: =IF(OR(J6>=140,K6>=90),2,0) -> 2 | R6: =SUM(L6:Q6) -> 11 | AD6: x | AF6: =IF(COUNTIF(S6:Z6,"X")>=2,"Có","Không") -> Không | AG6: =IF(COUNTIF(AA6:AE6,"X")>=3,"Có","Không") -> Không | AH6: =IF((R6)>=6,"Có","Không") -> Có | AI6: =IF((R6)>=6,"Có","Không") -> Có | AJ6: =IF(OR(J6>=140,K6>=90),"Có","Không") -> Có | AK6: ấp Biển Đông B, Phường Hiệp Thành, Tỉnh Cà Mau | AL6: 46053 | AM6: ="Tháng "&MONTH(AL6) -> Tháng 1 | AN6: =LEFT(AK6,FIND(",",AK6)-1) -> ấp Biển Đông B
A7: THẠCH THỊ PHOL | B7: Nữ | C7: 01/01/1960 | D7: =DATEDIF(C7,TODAY(),"Y") -> 66 | E7: Không | F7: 158 | G7: 58 | H7: =G7/((F7/100)*(F7/100)) -> 23.233456 | I7: 65 | J7: 130 | K7: 80 | L7: =IF(B7="Nữ",0,2) -> 0 | M7: =IF(D7<45,0,IF(D7<=49,1,2)) -> 2 | N7: =IF(E7="Có",4,0) -> 0 | O7: =IF(H7<23,0,IF(H7<27.5,3,5)) -> 3 | P7: =IF(OR(AND(B7="Nam",I7>=90),AND(B7="Nữ",I7>=80)),2,0) -> 0 | Q7: =IF(OR(J7>=140,K7>=90),2,0) -> 0 | R7: =SUM(L7:Q7) -> 5 | AD7: x | AF7: =IF(COUNTIF(S7:Z7,"X")>=2,"Có","Không") -> Không | AG7: =IF(COUNTIF(AA7:AE7,"X")>=3,"Có","Không") -> Không | AH7: =IF((R7)>=6,"Có","Không") -> Không | AI7: =IF((R7)>=6,"Có","Không") -> Không | AJ7: =IF(OR(J7>=140,K7>=90),"Có","Không") -> Không | AK7: ấp Biển Tây A, Xã Vĩnh Trạch Đông, Thành phố Bạc Liêu, Tỉnh Bạc Liêu | AL7: 46053 | AM7: ="Tháng "&MONTH(AL7) -> Tháng 1 | AN7: =LEFT(AK7,FIND(",",AK7)-1) -> ấp Biển Tây A
A8: MAI THANH MẬU | B8: Nam | C8: 01/01/1967 | D8: =DATEDIF(C8,TODAY(),"Y") -> 59 | E8: Không | F8: 169 | G8: 69 | H8: =G8/((F8/100)*(F8/100)) -> 24.158818 | I8: 84 | J8: 130 | K8: 80 | L8: =IF(B8="Nữ",0,2) -> 2 | M8: =IF(D8<45,0,IF(D8<=49,1,2)) -> 2 | N8: =IF(E8="Có",4,0) -> 0 | O8: =IF(H8<23,0,IF(H8<27.5,3,5)) -> 3 | P8: =IF(OR(AND(B8="Nam",I8>=90),AND(B8="Nữ",I8>=80)),2,0) -> 0 | Q8: =IF(OR(J8>=140,K8>=90),2,0) -> 0 | R8: =SUM(L8:Q8) -> 7 | AD8: x | AF8: =IF(COUNTIF(S8:Z8,"X")>=2,"Có","Không") -> Không | AG8: =IF(COUNTIF(AA8:AE8,"X")>=3,"Có","Không") -> Không | AH8: =IF((R8)>=6,"Có","Không") -> Có | AI8: =IF((R8)>=6,"Có","Không") -> Có | AJ8: =IF(OR(J8>=140,K8>=90),"Có","Không") -> Không | AK8: ấp Biển Đông B, Xã Vĩnh Trạch Đông, Thành phố Bạc Liêu, Tỉnh Bạc Liêu | AL8: 46053 | AM8: ="Tháng "&MONTH(AL8) -> Tháng 1 | AN8: =LEFT(AK8,FIND(",",AK8)-1) -> ấp Biển Đông B
A9: NGUYỄN VĂN NHỜ | B9: Nam | C9: 01/01/1954 | D9: =DATEDIF(C9,TODAY(),"Y") -> 72 | E9: Không | F9: 169 | G9: 69 | H9: =G9/((F9/100)*(F9/100)) -> 24.158818 | I9: 90 | J9: 130 | K9: 80 | L9: =IF(B9="Nữ",0,2) -> 2 | M9: =IF(D9<45,0,IF(D9<=49,1,2)) -> 2 | N9: =IF(E9="Có",4,0) -> 0 | O9: =IF(H9<23,0,IF(H9<27.5,3,5)) -> 3 | P9: =IF(OR(AND(B9="Nam",I9>=90),AND(B9="Nữ",I9>=80)),2,0) -> 2 | Q9: =IF(OR(J9>=140,K9>=90),2,0) -> 0 | R9: =SUM(L9:Q9) -> 9 | AD9: x | AF9: =IF(COUNTIF(S9:Z9,"X")>=2,"Có","Không") -> Không | AG9: =IF(COUNTIF(AA9:AE9,"X")>=3,"Có","Không") -> Không | AH9: =IF((R9)>=6,"Có","Không") -> Có | AI9: =IF((R9)>=6,"Có","Không") -> Có | AJ9: =IF(OR(J9>=140,K9>=90),"Có","Không") -> Không | AK9: Ấp Giồng Nhãn, Xã Hiệp Thành, Thành phố Bạc Liêu, Tỉnh Bạc Liêu | AL9: 46053 | AM9: ="Tháng "&MONTH(AL9) -> Tháng 1 | AN9: =LEFT(AK9,FIND(",",AK9)-1) -> Ấp Giồng Nhãn
A10: NGUYỄN THỊ BÔNG | B10: Nữ | C10: 01/01/1945 | D10: =DATEDIF(C10,TODAY(),"Y") -> 81 | E10: Không | F10: 160 | G10: 78 | H10: =G10/((F10/100)*(F10/100)) -> 30.46875 | I10: 74 | J10: 180 | K10: 90 | L10: =IF(B10="Nữ",0,2) -> 0 | M10: =IF(D10<45,0,IF(D10<=49,1,2)) -> 2 | N10: =IF(E10="Có",4,0) -> 0 | O10: =IF(H10<23,0,IF(H10<27.5,3,5)) -> 5 | P10: =IF(OR(AND(B10="Nam",I10>=90),AND(B10="Nữ",I10>=80)),2,0) -> 0 | Q10: =IF(OR(J10>=140,K10>=90),2,0) -> 2 | R10: =SUM(L10:Q10) -> 9 | AD10: x | AF10: =IF(COUNTIF(S10:Z10,"X")>=2,"Có","Không") -> Không | AG10: =IF(COUNTIF(AA10:AE10,"X")>=3,"Có","Không") -> Không | AH10: =IF((R10)>=6,"Có","Không") -> Có | AI10: =IF((R10)>=6,"Có","Không") -> Có | AJ10: =IF(OR(J10>=140,K10>=90),"Có","Không") -> Có | AK10: Phường Hiệp Thành, Tỉnh Cà Mau | AL10: 46053 | AM10: ="Tháng "&MONTH(AL10) -> Tháng 1 | AN10: =LEFT(AK10,FIND(",",AK10)-1) -> Phường Hiệp Thành
A11: THẠCH TY | B11: Nam | C11: 01/01/1948 | D11: =DATEDIF(C11,TODAY(),"Y") -> 78 | E11: Không | F11: 169 | G11: 69 | H11: =G11/((F11/100)*(F11/100)) -> 24.158818 | I11: 96 | J11: 140 | K11: 80 | L11: =IF(B11="Nữ",0,2) -> 2 | M11: =IF(D11<45,0,IF(D11<=49,1,2)) -> 2 | N11: =IF(E11="Có",4,0) -> 0 | O11: =IF(H11<23,0,IF(H11<27.5,3,5)) -> 3 | P11: =IF(OR(AND(B11="Nam",I11>=90),AND(B11="Nữ",I11>=80)),2,0) -> 2 | Q11: =IF(OR(J11>=140,K11>=90),2,0) -> 2 | R11: =SUM(L11:Q11) -> 11 | AD11: x | AF11: =IF(COUNTIF(S11:Z11,"X")>=2,"Có","Không") -> Không | AG11: =IF(COUNTIF(AA11:AE11,"X")>=3,"Có","Không") -> Không | AH11: =IF((R11)>=6,"Có","Không") -> Có | AI11: =IF((R11)>=6,"Có","Không") -> Có | AJ11: =IF(OR(J11>=140,K11>=90),"Có","Không") -> Có | AK11: Phường Hiệp Thành, Tỉnh Cà Mau | AL11: 46053 | AM11: ="Tháng "&MONTH(AL11) -> Tháng 1 | AN11: =LEFT(AK11,FIND(",",AK11)-1) -> Phường Hiệp Thành
A12: TRƯƠNG HAI | B12: Nam | C12: 01/01/1952 | D12: =DATEDIF(C12,TODAY(),"Y") -> 74 | E12: Không | F12: 168 | G12: 68 | H12: =G12/((F12/100)*(F12/100)) -> 24.092971 | I12: 96 | J12: 140 | K12: 80 | L12: =IF(B12="Nữ",0,2) -> 2 | M12: =IF(D12<45,0,IF(D12<=49,1,2)) -> 2 | N12: =IF(E12="Có",4,0) -> 0 | O12: =IF(H12<23,0,IF(H12<27.5,3,5)) -> 3 | P12: =IF(OR(AND(B12="Nam",I12>=90),AND(B12="Nữ",I12>=80)),2,0) -> 2 | Q12: =IF(OR(J12>=140,K12>=90),2,0) -> 2 | R12: =SUM(L12:Q12) -> 11 | AD12: x | AF12: =IF(COUNTIF(S12:Z12,"X")>=2,"Có","Không") -> Không | AG12: =IF(COUNTIF(AA12:AE12,"X")>=3,"Có","Không") -> Không | AH12: =IF((R12)>=6,"Có","Không") -> Có | AI12: =IF((R12)>=6,"Có","Không") -> Có | AJ12: =IF(OR(J12>=140,K12>=90),"Có","Không") -> Có | AK12: Ấp Biển Đông B, Phường Hiệp Thành, Tỉnh Cà Mau | AL12: 46053 | AM12: ="Tháng "&MONTH(AL12) -> Tháng 1 | AN12: =LEFT(AK12,FIND(",",AK12)-1) -> Ấp Biển Đông B
A13: CHIÊM LIN ĐA | B13: Nữ | C13: 01/01/1984 | D13: =DATEDIF(C13,TODAY(),"Y") -> 42 | E13: Có | F13: 158 | G13: 58 | H13: =G13/((F13/100)*(F13/100)) -> 23.233456 | I13: 69 | J13: 120 | K13: 80 | L13: =IF(B13="Nữ",0,2) -> 0 | M13: =IF(D13<45,0,IF(D13<=49,1,2)) -> 0 | N13: =IF(E13="Có",4,0) -> 4 | O13: =IF(H13<23,0,IF(H13<27.5,3,5)) -> 3 | P13: =IF(OR(AND(B13="Nam",I13>=90),AND(B13="Nữ",I13>=80)),2,0) -> 0 | Q13: =IF(OR(J13>=140,K13>=90),2,0) -> 0 | R13: =SUM(L13:Q13) -> 7 | AD13: x | AF13: =IF(COUNTIF(S13:Z13,"X")>=2,"Có","Không") -> Không | AG13: =IF(COUNTIF(AA13:AE13,"X")>=3,"Có","Không") -> Không | AH13: =IF((R13)>=6,"Có","Không") -> Có | AI13: =IF((R13)>=6,"Có","Không") -> Có | AJ13: =IF(OR(J13>=140,K13>=90),"Có","Không") -> Không | AK13: Biển Đông B, Phường Hiệp Thành, Tỉnh Cà Mau | AL13: 46053 | AM13: ="Tháng "&MONTH(AL13) -> Tháng 1 | AN13: =LEFT(AK13,FIND(",",AK13)-1) -> Biển Đông B
A14: KHƯU THỊ HẾN | B14: Nữ | C14: 01/01/1961 | D14: =DATEDIF(C14,TODAY(),"Y") -> 65 | E14: Không | F14: 158 | G14: 55 | H14: =G14/((F14/100)*(F14/100)) -> 22.031726 | I14: 88 | J14: 120 | K14: 70 | L14: =IF(B14="Nữ",0,2) -> 0 | M14: =IF(D14<45,0,IF(D14<=49,1,2)) -> 2 | N14: =IF(E14="Có",4,0) -> 0 | O14: =IF(H14<23,0,IF(H14<27.5,3,5)) -> 0 | P14: =IF(OR(AND(B14="Nam",I14>=90),AND(B14="Nữ",I14>=80)),2,0) -> 2 | Q14: =IF(OR(J14>=140,K14>=90),2,0) -> 0 | R14: =SUM(L14:Q14) -> 4 | AD14: x | AF14: =IF(COUNTIF(S14:Z14,"X")>=2,"Có","Không") -> Không | AG14: =IF(COUNTIF(AA14:AE14,"X")>=3,"Có","Không") -> Không | AH14: =IF((R14)>=6,"Có","Không") -> Không | AI14: =IF((R14)>=6,"Có","Không") -> Không | AJ14: =IF(OR(J14>=140,K14>=90),"Có","Không") -> Không | AK14: Phường Hiệp Thành, tỉnh Cà Mau | AL14: 46053 | AM14: ="Tháng "&MONTH(AL14) -> Tháng 1 | AN14: =LEFT(AK14,FIND(",",AK14)-1) -> Phường Hiệp Thành
A15: NGUYỄN THỊ XUYẾN | B15: Nữ | C15: 01/01/1954 | D15: =DATEDIF(C15,TODAY(),"Y") -> 72 | E15: Không | F15: 158 | G15: 58 | H15: =G15/((F15/100)*(F15/100)) -> 23.233456 | I15: 82 | J15: 140 | K15: 80 | L15: =IF(B15="Nữ",0,2) -> 0 | M15: =IF(D15<45,0,IF(D15<=49,1,2)) -> 2 | N15: =IF(E15="Có",4,0) -> 0 | O15: =IF(H15<23,0,IF(H15<27.5,3,5)) -> 3 | P15: =IF(OR(AND(B15="Nam",I15>=90),AND(B15="Nữ",I15>=80)),2,0) -> 2 | Q15: =IF(OR(J15>=140,K15>=90),2,0) -> 2 | R15: =SUM(L15:Q15) -> 9 | AD15: x | AF15: =IF(COUNTIF(S15:Z15,"X")>=2,"Có","Không") -> Không | AG15: =IF(COUNTIF(AA15:AE15,"X")>=3,"Có","Không") -> Không | AH15: =IF((R15)>=6,"Có","Không") -> Có | AI15: =IF((R15)>=6,"Có","Không") -> Có | AJ15: =IF(OR(J15>=140,K15>=90),"Có","Không") -> Có | AK15: Ấp Biển Tây A, Phường Bạc Liêu, Thành phố Bạc Liêu, Tỉnh Cà Mau | AL15: 46053 | AM15: ="Tháng "&MONTH(AL15) -> Tháng 1 | AN15: =LEFT(AK15,FIND(",",AK15)-1) -> Ấp Biển Tây A
... A81: NGUYỄN THANH HẢO | B81: Nam | C81: 01/01/1963 | D81: =DATEDIF(C81,TODAY(),"Y") -> 63 | E81: Không | F81: 169 | G81: 69 | H81: =G81/((F81/100)*(F81/100)) -> 24.158818 | I81: 89 | J81: 140 | K81: 80 | L81: =IF(B81="Nữ",0,2) -> 2 | M81: =IF(D81<45,0,IF(D81<=49,1,2)) -> 2 | N81: =IF(E81="Có",4,0) -> 0 | O81: =IF(H81<23,0,IF(H81<27.5,3,5)) -> 3 | P81: =IF(OR(AND(B81="Nam",I81>=90),AND(B81="Nữ",I81>=80)),2,0) -> 0 | Q81: =IF(OR(J81>=140,K81>=90),2,0) -> 2 | R81: =SUM(L81:Q81) -> 9 | AD81: x | AF81: =IF(COUNTIF(S81:Z81,"X")>=2,"Có","Không") -> Không | AG81: =IF(COUNTIF(AA81:AE81,"X")>=3,"Có","Không") -> Không | AH81: =IF((R81)>=6,"Có","Không") -> Có | AI81: =IF((R81)>=6,"Có","Không") -> Có | AJ81: =IF(OR(J81>=140,K81>=90),"Có","Không") -> Có | AK81: Ấp Biển Tây A, Phường Hiệp Thành, Tỉnh Cà Mau | AL81: 46053 | AM81: ="Tháng "&MONTH(AL81) -> Tháng 1 | AN81: =LEFT(AK81,FIND(",",AK81)-1) -> Ấp Biển Tây A
A82: KHƯU VĂN HÙNG | B82: Nam | C82: 24838 | D82: =DATEDIF(C82,TODAY(),"Y") -> 58 | E82: Có | F82: 163 | G82: 54 | H82: =G82/((F82/100)*(F82/100)) -> 20.324438 | I82: 100 | J82: 150 | K82: 80 | L82: =IF(B82="Nữ",0,2) -> 2 | M82: =IF(D82<45,0,IF(D82<=49,1,2)) -> 2 | N82: =IF(E82="Có",4,0) -> 4 | O82: =IF(H82<23,0,IF(H82<27.5,3,5)) -> 0 | P82: =IF(OR(AND(B82="Nam",I82>=90),AND(B82="Nữ",I82>=80)),2,0) -> 2 | Q82: =IF(OR(J82>=140,K82>=90),2,0) -> 2 | R82: =SUM(L82:Q82) -> 12 | AD82: x | AF82: =IF(COUNTIF(S82:Z82,"X")>=2,"Có","Không") -> Không | AG82: =IF(COUNTIF(AA82:AE82,"X")>=3,"Có","Không") -> Không | AH82: =IF((R82)>=6,"Có","Không") -> Có | AI82: =IF((R82)>=6,"Có","Không") -> Có | AJ82: =IF(OR(J82>=140,K82>=90),"Có","Không") -> Có | AK82: Phường Hiệp Thành, Tỉnh Cà Mau | AL82: 46053 | AM82: ="Tháng "&MONTH(AL82) -> Tháng 1 | AN82: Phường Hiệp Thành
A83: TRẦN THỊ MỸ | B83: Nữ | C83: 21551 | D83: =DATEDIF(C83,TODAY(),"Y") -> 67 | E83: Không | F83: 150 | G83: 60 | H83: =G83/((F83/100)*(F83/100)) -> 26.666667 | I83: 97 | J83: 120 | K83: 80 | L83: =IF(B83="Nữ",0,2) -> 0 | M83: =IF(D83<45,0,IF(D83<=49,1,2)) -> 2 | N83: =IF(E83="Có",4,0) -> 0 | O83: =IF(H83<23,0,IF(H83<27.5,3,5)) -> 3 | P83: =IF(OR(AND(B83="Nam",I83>=90),AND(B83="Nữ",I83>=80)),2,0) -> 2 | Q83: =IF(OR(J83>=140,K83>=90),2,0) -> 0 | R83: =SUM(L83:Q83) -> 7 | AD83: x | AF83: =IF(COUNTIF(S83:Z83,"X")>=2,"Có","Không") -> Không | AG83: =IF(COUNTIF(AA83:AE83,"X")>=3,"Có","Không") -> Không | AH83: =IF((R83)>=6,"Có","Không") -> Có | AI83: =IF((R83)>=6,"Có","Không") -> Có | AJ83: =IF(OR(J83>=140,K83>=90),"Có","Không") -> Không | AK83: Phường Hiệp Thành, Tỉnh Cà Mau | AL83: 46053 | AM83: ="Tháng "&MONTH(AL83) -> Tháng 1 | AN83: Phường Hiệp Thành
A84: TÁC VĂN HIẾN | B84: Nam | C84: 24473 | D84: =DATEDIF(C84,TODAY(),"Y") -> 59 | E84: Không | F84: 163 | G84: 54 | H84: =G84/((F84/100)*(F84/100)) -> 20.324438 | I84: 82 | J84: 130 | K84: 80 | L84: =IF(B84="Nữ",0,2) -> 2 | M84: =IF(D84<45,0,IF(D84<=49,1,2)) -> 2 | N84: =IF(E84="Có",4,0) -> 0 | O84: =IF(H84<23,0,IF(H84<27.5,3,5)) -> 0 | P84: =IF(OR(AND(B84="Nam",I84>=90),AND(B84="Nữ",I84>=80)),2,0) -> 0 | Q84: =IF(OR(J84>=140,K84>=90),2,0) -> 0 | R84: =SUM(L84:Q84) -> 4 | AD84: x | AF84: =IF(COUNTIF(S84:Z84,"X")>=2,"Có","Không") -> Không | AG84: =IF(COUNTIF(AA84:AE84,"X")>=3,"Có","Không") -> Không | AH84: =IF((R84)>=6,"Có","Không") -> Không | AI84: =IF((R84)>=6,"Có","Không") -> Không | AJ84: =IF(OR(J84>=140,K84>=90),"Có","Không") -> Không | AK84: Phường Hiệp Thành, Tỉnh Cà Mau | AL84: 46053 | AM84: ="Tháng "&MONTH(AL84) -> Tháng 1 | AN84: Phường Hiệp Thành
A85: HUỲNH THỊ NGỌC | B85: Nữ | C85: 24473 | D85: =DATEDIF(C85,TODAY(),"Y") -> 59 | E85: Không | F85: 169 | G85: 68 | H85: =G85/((F85/100)*(F85/100)) -> 23.80869 | I85: 76 | J85: 120 | K85: 80 | L85: =IF(B85="Nữ",0,2) -> 0 | M85: =IF(D85<45,0,IF(D85<=49,1,2)) -> 2 | N85: =IF(E85="Có",4,0) -> 0 | O85: =IF(H85<23,0,IF(H85<27.5,3,5)) -> 3 | P85: =IF(OR(AND(B85="Nam",I85>=90),AND(B85="Nữ",I85>=80)),2,0) -> 0 | Q85: =IF(OR(J85>=140,K85>=90),2,0) -> 0 | R85: =SUM(L85:Q85) -> 5 | AD85: x | AF85: =IF(COUNTIF(S85:Z85,"X")>=2,"Có","Không") -> Không | AG85: =IF(COUNTIF(AA85:AE85,"X")>=3,"Có","Không") -> Không | AH85: =IF((R85)>=6,"Có","Không") -> Không | AI85: =IF((R85)>=6,"Có","Không") -> Không | AJ85: =IF(OR(J85>=140,K85>=90),"Có","Không") -> Không | AK85: Phường Hiệp Thành, Tỉnh Cà Mau | AL85: 46053 | AM85: ="Tháng "&MONTH(AL85) -> Tháng 1 | AN85: Phường Hiệp Thành
A86: LÂM ÁI KHUÔI | B86: Nữ | C86: 27760 | D86: =DATEDIF(C86,TODAY(),"Y") -> 50 | E86: Không | F86: 158 | G86: 58 | H86: =G86/((F86/100)*(F86/100)) -> 23.233456 | I86: 89 | J86: 130 | K86: 80 | L86: =IF(B86="Nữ",0,2) -> 0 | M86: =IF(D86<45,0,IF(D86<=49,1,2)) -> 2 | N86: =IF(E86="Có",4,0) -> 0 | O86: =IF(H86<23,0,IF(H86<27.5,3,5)) -> 3 | P86: =IF(OR(AND(B86="Nam",I86>=90),AND(B86="Nữ",I86>=80)),2,0) -> 2 | Q86: =IF(OR(J86>=140,K86>=90),2,0) -> 0 | R86: =SUM(L86:Q86) -> 7 | AD86: x | AF86: =IF(COUNTIF(S86:Z86,"X")>=2,"Có","Không") -> Không | AG86: =IF(COUNTIF(AA86:AE86,"X")>=3,"Có","Không") -> Không | AH86: =IF((R86)>=6,"Có","Không") -> Có | AI86: =IF((R86)>=6,"Có","Không") -> Có | AJ86: =IF(OR(J86>=140,K86>=90),"Có","Không") -> Không | AK86: Phường Hiệp Thành, Tỉnh Cà Mau | AL86: 46053 | AM86: ="Tháng "&MONTH(AL86) -> Tháng 1 | AN86: Phường Hiệp Thành
A87: LÂM THỊ HIÊM | B87: Nam | C87: 23743 | D87: =DATEDIF(C87,TODAY(),"Y") -> 61 | E87: Không | F87: 160 | G87: 70 | H87: =G87/((F87/100)*(F87/100)) -> 27.34375 | I87: 81 | J87: 140 | K87: 80 | L87: =IF(B87="Nữ",0,2) -> 2 | M87: =IF(D87<45,0,IF(D87<=49,1,2)) -> 2 | N87: =IF(E87="Có",4,0) -> 0 | O87: =IF(H87<23,0,IF(H87<27.5,3,5)) -> 3 | P87: =IF(OR(AND(B87="Nam",I87>=90),AND(B87="Nữ",I87>=80)),2,0) -> 0 | Q87: =IF(OR(J87>=140,K87>=90),2,0) -> 2 | R87: =SUM(L87:Q87) -> 9 | AD87: x | AF87: =IF(COUNTIF(S87:Z87,"X")>=2,"Có","Không") -> Không | AG87: =IF(COUNTIF(AA87:AE87,"X")>=3,"Có","Không") -> Không | AH87: =IF((R87)>=6,"Có","Không") -> Có | AI87: =IF((R87)>=6,"Có","Không") -> Có | AJ87: =IF(OR(J87>=140,K87>=90),"Có","Không") -> Có | AK87: Phường Hiệp Thành, Tỉnh Cà Mau | AL87: 46053 | AM87: ="Tháng "&MONTH(AL87) -> Tháng 1 | AN87: Phường Hiệp Thành
A88: SƠN CHUM | B88: Nam | C88: 20090 | D88: =DATEDIF(C88,TODAY(),"Y") -> 71 | E88: Không | F88: 158 | G88: 58 | H88: =G88/((F88/100)*(F88/100)) -> 23.233456 | I88: 71 | J88: 120 | K88: 80 | L88: =IF(B88="Nữ",0,2) -> 2 | M88: =IF(D88<45,0,IF(D88<=49,1,2)) -> 2 | N88: =IF(E88="Có",4,0) -> 0 | O88: =IF(H88<23,0,IF(H88<27.5,3,5)) -> 3 | P88: =IF(OR(AND(B88="Nam",I88>=90),AND(B88="Nữ",I88>=80)),2,0) -> 0 | Q88: =IF(OR(J88>=140,K88>=90),2,0) -> 0 | R88: =SUM(L88:Q88) -> 7 | AD88: x | AF88: =IF(COUNTIF(S88:Z88,"X")>=2,"Có","Không") -> Không | AG88: =IF(COUNTIF(AA88:AE88,"X")>=3,"Có","Không") -> Không | AH88: =IF((R88)>=6,"Có","Không") -> Có | AI88: =IF((R88)>=6,"Có","Không") -> Có | AJ88: =IF(OR(J88>=140,K88>=90),"Có","Không") -> Không | AK88: Phường Hiệp Thành, Tỉnh Cà Mau | AL88: 46053 | AM88: ="Tháng "&MONTH(AL88) -> Tháng 1 | AN88: Phường Hiệp Thành
A89: HÀ NGỌC HẠNH | B89: Nữ | C89: 26299 | D89: =DATEDIF(C89,TODAY(),"Y") -> 54 | E89: Không | F89: 169 | G89: 68 | H89: =G89/((F89/100)*(F89/100)) -> 23.80869 | I89: 76 | J89: 140 | K89: 80 | L89: =IF(B89="Nữ",0,2) -> 0 | M89: =IF(D89<45,0,IF(D89<=49,1,2)) -> 2 | N89: =IF(E89="Có",4,0) -> 0 | O89: =IF(H89<23,0,IF(H89<27.5,3,5)) -> 3 | P89: =IF(OR(AND(B89="Nam",I89>=90),AND(B89="Nữ",I89>=80)),2,0) -> 0 | Q89: =IF(OR(J89>=140,K89>=90),2,0) -> 2 | R89: =SUM(L89:Q89) -> 7 | AD89: x | AF89: =IF(COUNTIF(S89:Z89,"X")>=2,"Có","Không") -> Không | AG89: =IF(COUNTIF(AA89:AE89,"X")>=3,"Có","Không") -> Không | AH89: =IF((R89)>=6,"Có","Không") -> Có | AI89: =IF((R89)>=6,"Có","Không") -> Có | AJ89: =IF(OR(J89>=140,K89>=90),"Có","Không") -> Có | AK89: Phường Hiệp Thành, Tỉnh Cà Mau | AL89: 46053 | AM89: ="Tháng "&MONTH(AL89) -> Tháng 1 | AN89: Phường Hiệp Thành
A90: SƠN THỊ HỒNG | B90: Nữ | C90: 21186 | D90: =DATEDIF(C90,TODAY(),"Y") -> 68 | E90: Có | F90: 169 | G90: 68 | H90: =G90/((F90/100)*(F90/100)) -> 23.80869 | I90: 73 | J90: 160 | K90: 80 | L90: =IF(B90="Nữ",0,2) -> 0 | M90: =IF(D90<45,0,IF(D90<=49,1,2)) -> 2 | N90: =IF(E90="Có",4,0) -> 4 | O90: =IF(H90<23,0,IF(H90<27.5,3,5)) -> 3 | P90: =IF(OR(AND(B90="Nam",I90>=90),AND(B90="Nữ",I90>=80)),2,0) -> 0 | Q90: =IF(OR(J90>=140,K90>=90),2,0) -> 2 | R90: =SUM(L90:Q90) -> 11 | AD90: x | AF90: =IF(COUNTIF(S90:Z90,"X")>=2,"Có","Không") -> Không | AG90: =IF(COUNTIF(AA90:AE90,"X")>=3,"Có","Không") -> Không | AH90: =IF((R90)>=6,"Có","Không") -> Có | AI90: =IF((R90)>=6,"Có","Không") -> Có | AJ90: =IF(OR(J90>=140,K90>=90),"Có","Không") -> Có | AK90: Phường Hiệp Thành, Tỉnh Cà Mau | AL90: 46053 | AM90: ="Tháng "&MONTH(AL90) -> Tháng 1 | AN90: Phường Hiệp Thành
A91: NGUYỄN VĂN HÙNG | B91: Nam | C91: 24108 | D91: =DATEDIF(C91,TODAY(),"Y") -> 60 | E91: Có | F91: 162 | G91: 76 | H91: =G91/((F91/100)*(F91/100)) -> 28.959 | I91: 93 | J91: 120 | K91: 70 | L91: =IF(B91="Nữ",0,2) -> 2 | M91: =IF(D91<45,0,IF(D91<=49,1,2)) -> 2 | N91: =IF(E91="Có",4,0) -> 4 | O91: =IF(H91<23,0,IF(H91<27.5,3,5)) -> 5 | P91: =IF(OR(AND(B91="Nam",I91>=90),AND(B91="Nữ",I91>=80)),2,0) -> 2 | Q91: =IF(OR(J91>=140,K91>=90),2,0) -> 0 | R91: =SUM(L91:Q91) -> 15 | AD91: x | AF91: =IF(COUNTIF(S91:Z91,"X")>=2,"Có","Không") -> Không | AG91: =IF(COUNTIF(AA91:AE91,"X")>=3,"Có","Không") -> Không | AH91: =IF((R91)>=6,"Có","Không") -> Có | AI91: =IF((R91)>=6,"Có","Không") -> Có | AJ91: =IF(OR(J91>=140,K91>=90),"Có","Không") -> Không | AK91: Phường Hiệp Thành, Tỉnh Cà Mau | AL91: 46053 | AM91: ="Tháng "&MONTH(AL91) -> Tháng 1 | AN91: Phường Hiệp Thành
A92: NGUYỄN VĂN TỨC | B92: Nam | C92: 21916 | D92: =DATEDIF(C92,TODAY(),"Y") -> 66 | E92: Không | F92: 160 | G92: 55 | H92: =G92/((F92/100)*(F92/100)) -> 21.484375 | I92: 83 | J92: 120 | K92: 80 | L92: =IF(B92="Nữ",0,2) -> 2 | M92: =IF(D92<45,0,IF(D92<=49,1,2)) -> 2 | N92: =IF(E92="Có",4,0) -> 0 | O92: =IF(H92<23,0,IF(H92<27.5,3,5)) -> 0 | P92: =IF(OR(AND(B92="Nam",I92>=90),AND(B92="Nữ",I92>=80)),2,0) -> 0 | Q92: =IF(OR(J92>=140,K92>=90),2,0) -> 0 | R92: =SUM(L92:Q92) -> 4 | AD92: x | AF92: =IF(COUNTIF(S92:Z92,"X")>=2,"Có","Không") -> Không | AG92: =IF(COUNTIF(AA92:AE92,"X")>=3,"Có","Không") -> Không | AH92: =IF((R92)>=6,"Có","Không") -> Không | AI92: =IF((R92)>=6,"Có","Không") -> Không | AJ92: =IF(OR(J92>=140,K92>=90),"Có","Không") -> Không | AK92: Phường Hiệp Thành, Tỉnh Cà Mau | AL92: 46053 | AM92: ="Tháng "&MONTH(AL92) -> Tháng 1 | AN92: Phường Hiệp Thành
A93: THẠCH THỊ SÀ PHƯƠL | B93: Nữ | C93: 23012 | D93: =DATEDIF(C93,TODAY(),"Y") -> 63 | E93: Không | F93: 158 | G93: 58 | H93: =G93/((F93/100)*(F93/100)) -> 23.233456 | I93: 86 | J93: 120 | K93: 80 | L93: =IF(B93="Nữ",0,2) -> 0 | M93: =IF(D93<45,0,IF(D93<=49,1,2)) -> 2 | N93: =IF(E93="Có",4,0) -> 0 | O93: =IF(H93<23,0,IF(H93<27.5,3,5)) -> 3 | P93: =IF(OR(AND(B93="Nam",I93>=90),AND(B93="Nữ",I93>=80)),2,0) -> 2 | Q93: =IF(OR(J93>=140,K93>=90),2,0) -> 0 | R93: =SUM(L93:Q93) -> 7 | AD93: x | AF93: =IF(COUNTIF(S93:Z93,"X")>=2,"Có","Không") -> Không | AG93: =IF(COUNTIF(AA93:AE93,"X")>=3,"Có","Không") -> Không | AH93: =IF((R93)>=6,"Có","Không") -> Có | AI93: =IF((R93)>=6,"Có","Không") -> Có | AJ93: =IF(OR(J93>=140,K93>=90),"Có","Không") -> Không | AK93: Phường Hiệp Thành, Tỉnh Cà Mau | AL93: 46053 | AM93: ="Tháng "&MONTH(AL93) -> Tháng 1 | AN93: Phường Hiệp Thành
... A153: DANH THỊ EM | B153: Nữ | C153: 19360 | D153: =DATEDIF(C153,TODAY(),"Y") -> 73 | E153: Có | F153: 160 | G153: 49 | H153: =G153/((F153/100)*(F153/100)) -> 19.140625 | I153: 84 | J153: 120 | K153: 70 | L153: =IF(B153="Nữ",0,2) -> 0 | M153: =IF(D153<45,0,IF(D153<=49,1,2)) -> 2 | N153: =IF(E153="Có",4,0) -> 4 | O153: =IF(H153<23,0,IF(H153<27.5,3,5)) -> 0 | P153: =IF(OR(AND(B153="Nam",I153>=90),AND(B153="Nữ",I153>=80)),2,0) -> 2 | Q153: =IF(OR(J153>=140,K153>=90),2,0) -> 0 | R153: =SUM(L153:Q153) -> 8 | AD153: x | AF153: =IF(COUNTIF(S153:Z153,"X")>=2,"Có","Không") -> Không | AG153: =IF(COUNTIF(AA153:AE153,"X")>=3,"Có","Không") -> Không | AH153: =IF((R153)>=6,"Có","Không") -> Có | AI153: =IF((R153)>=6,"Có","Không") -> Có | AJ153: =IF(OR(J153>=140,K153>=90),"Có","Không") -> Không | AK153: Phường Hiệp Thành, Tỉnh Cà Mau | AL153: 46053 | AM153: ="Tháng "&MONTH(AL153) -> Tháng 1 | AN153: Phường Hiệp Thành
A154: TRƯƠNG VĂN HỒNG | B154: Nam | C154: 01/01/1968 | D154: =DATEDIF(C154,TODAY(),"Y") -> 58 | E154: Có | F154: 163 | G154: 69 | H154: =G154/((F154/100)*(F154/100)) -> 25.970116 | I154: 99 | J154: 120 | K154: 80 | L154: =IF(B154="Nữ",0,2) -> 2 | M154: =IF(D154<45,0,IF(D154<=49,1,2)) -> 2 | N154: =IF(E154="Có",4,0) -> 4 | O154: =IF(H154<23,0,IF(H154<27.5,3,5)) -> 3 | P154: =IF(OR(AND(B154="Nam",I154>=90),AND(B154="Nữ",I154>=80)),2,0) -> 2 | Q154: =IF(OR(J154>=140,K154>=90),2,0) -> 0 | R154: =SUM(L154:Q154) -> 13 | AD154: x | AF154: =IF(COUNTIF(S154:Z154,"X")>=2,"Có","Không") -> Không | AG154: =IF(COUNTIF(AA154:AE154,"X")>=3,"Có","Không") -> Không | AH154: =IF((R154)>=6,"Có","Không") -> Có | AI154: =IF((R154)>=6,"Có","Không") -> Có | AJ154: =IF(OR(J154>=140,K154>=90),"Có","Không") -> Không | AK154: Phường Hiệp Thành, tỉnh Cà Mau | AL154: 46081 | AM154: ="Tháng "&MONTH(AL154) -> Tháng 2 | AN154: =LEFT(AK154,FIND(",",AK154)-1) -> Phường Hiệp Thành
A155: HUỲNH VĂN BÍ | B155: Nam | C155: 01/01/1952 | D155: =DATEDIF(C155,TODAY(),"Y") -> 74 | E155: Không | F155: 170 | G155: 57 | H155: =G155/((F155/100)*(F155/100)) -> 19.723183 | I155: 81 | J155: 120 | K155: 80 | L155: =IF(B155="Nữ",0,2) -> 2 | M155: =IF(D155<45,0,IF(D155<=49,1,2)) -> 2 | N155: =IF(E155="Có",4,0) -> 0 | O155: =IF(H155<23,0,IF(H155<27.5,3,5)) -> 0 | P155: =IF(OR(AND(B155="Nam",I155>=90),AND(B155="Nữ",I155>=80)),2,0) -> 0 | Q155: =IF(OR(J155>=140,K155>=90),2,0) -> 0 | R155: =SUM(L155:Q155) -> 4 | AD155: x | AF155: =IF(COUNTIF(S155:Z155,"X")>=2,"Có","Không") -> Không | AG155: =IF(COUNTIF(AA155:AE155,"X")>=3,"Có","Không") -> Không | AH155: =IF((R155)>=6,"Có","Không") -> Không | AI155: =IF((R155)>=6,"Có","Không") -> Không | AJ155: =IF(OR(J155>=140,K155>=90),"Có","Không") -> Không | AK155: Giống Nhãn, Phường Hiệp Thành, Tỉnh Cà Mau | AL155: 46081 | AM155: ="Tháng "&MONTH(AL155) -> Tháng 2 | AN155: =LEFT(AK155,FIND(",",AK155)-1) -> Giống Nhãn
A156: LIÊU XÚ MÉN | B156: Nữ | C156: 01/01/1969 | D156: =DATEDIF(C156,TODAY(),"Y") -> 57 | E156: Có | F156: 150 | G156: 32 | H156: =G156/((F156/100)*(F156/100)) -> 14.222222 | I156: 73 | J156: 120 | K156: 80 | L156: =IF(B156="Nữ",0,2) -> 0 | M156: =IF(D156<45,0,IF(D156<=49,1,2)) -> 2 | N156: =IF(E156="Có",4,0) -> 4 | O156: =IF(H156<23,0,IF(H156<27.5,3,5)) -> 0 | P156: =IF(OR(AND(B156="Nam",I156>=90),AND(B156="Nữ",I156>=80)),2,0) -> 0 | Q156: =IF(OR(J156>=140,K156>=90),2,0) -> 0 | R156: =SUM(L156:Q156) -> 6 | AD156: x | AF156: =IF(COUNTIF(S156:Z156,"X")>=2,"Có","Không") -> Không | AG156: =IF(COUNTIF(AA156:AE156,"X")>=3,"Có","Không") -> Không | AH156: =IF((R156)>=6,"Có","Không") -> Có | AI156: =IF((R156)>=6,"Có","Không") -> Có | AJ156: =IF(OR(J156>=140,K156>=90),"Có","Không") -> Không | AK156: Phường Hiệp Thành, Tỉnh Cà Mau | AL156: 46081 | AM156: ="Tháng "&MONTH(AL156) -> Tháng 2 | AN156: =LEFT(AK156,FIND(",",AK156)-1) -> Phường Hiệp Thành
A157: TRIỆU HỒNG CHƯƠNG | B157: Nam | C157: 01/01/1947 | D157: =DATEDIF(C157,TODAY(),"Y") -> 79 | E157: Không | F157: 169 | G157: 69 | H157: =G157/((F157/100)*(F157/100)) -> 24.158818 | I157: 100 | J157: 140 | K157: 80 | L157: =IF(B157="Nữ",0,2) -> 2 | M157: =IF(D157<45,0,IF(D157<=49,1,2)) -> 2 | N157: =IF(E157="Có",4,0) -> 0 | O157: =IF(H157<23,0,IF(H157<27.5,3,5)) -> 3 | P157: =IF(OR(AND(B157="Nam",I157>=90),AND(B157="Nữ",I157>=80)),2,0) -> 2 | Q157: =IF(OR(J157>=140,K157>=90),2,0) -> 2 | R157: =SUM(L157:Q157) -> 11 | AD157: x | AF157: =IF(COUNTIF(S157:Z157,"X")>=2,"Có","Không") -> Không | AG157: =IF(COUNTIF(AA157:AE157,"X")>=3,"Có","Không") -> Không | AH157: =IF((R157)>=6,"Có","Không") -> Có | AI157: =IF((R157)>=6,"Có","Không") -> Có | AJ157: =IF(OR(J157>=140,K157>=90),"Có","Không") -> Có | AK157: Ấp Biển Đông A, Phường Hiệp Thành, Tỉnh Cà Mau | AL157: 46081 | AM157: ="Tháng "&MONTH(AL157) -> Tháng 2 | AN157: =LEFT(AK157,FIND(",",AK157)-1) -> Ấp Biển Đông A
A158: NGUYỄN VĂN CHÂU | B158: Nam | C158: 01/01/1961 | D158: =DATEDIF(C158,TODAY(),"Y") -> 65 | E158: Có | F158: 169 | G158: 69 | H158: =G158/((F158/100)*(F158/100)) -> 24.158818 | I158: 96 | J158: 140 | K158: 80 | L158: =IF(B158="Nữ",0,2) -> 2 | M158: =IF(D158<45,0,IF(D158<=49,1,2)) -> 2 | N158: =IF(E158="Có",4,0) -> 4 | O158: =IF(H158<23,0,IF(H158<27.5,3,5)) -> 3 | P158: =IF(OR(AND(B158="Nam",I158>=90),AND(B158="Nữ",I158>=80)),2,0) -> 2 | Q158: =IF(OR(J158>=140,K158>=90),2,0) -> 2 | R158: =SUM(L158:Q158) -> 15 | AD158: x | AF158: =IF(COUNTIF(S158:Z158,"X")>=2,"Có","Không") -> Không | AG158: =IF(COUNTIF(AA158:AE158,"X")>=3,"Có","Không") -> Không | AH158: =IF((R158)>=6,"Có","Không") -> Có | AI158: =IF((R158)>=6,"Có","Không") -> Có | AJ158: =IF(OR(J158>=140,K158>=90),"Có","Không") -> Có | AK158: Ấp Biển Đông A, Phường Hiệp Thành, Tỉnh Cà Mau | AL158: 46081 | AM158: ="Tháng "&MONTH(AL158) -> Tháng 2 | AN158: =LEFT(AK158,FIND(",",AK158)-1) -> Ấp Biển Đông A
A159: TRẦN BÒ | B159: Nam | C159: 01/01/1974 | D159: =DATEDIF(C159,TODAY(),"Y") -> 52 | E159: Có | F159: 169 | G159: 69 | H159: =G159/((F159/100)*(F159/100)) -> 24.158818 | I159: 90 | J159: 160 | K159: 80 | L159: =IF(B159="Nữ",0,2) -> 2 | M159: =IF(D159<45,0,IF(D159<=49,1,2)) -> 2 | N159: =IF(E159="Có",4,0) -> 4 | O159: =IF(H159<23,0,IF(H159<27.5,3,5)) -> 3 | P159: =IF(OR(AND(B159="Nam",I159>=90),AND(B159="Nữ",I159>=80)),2,0) -> 2 | Q159: =IF(OR(J159>=140,K159>=90),2,0) -> 2 | R159: =SUM(L159:Q159) -> 15 | AD159: x | AF159: =IF(COUNTIF(S159:Z159,"X")>=2,"Có","Không") -> Không | AG159: =IF(COUNTIF(AA159:AE159,"X")>=3,"Có","Không") -> Không | AH159: =IF((R159)>=6,"Có","Không") -> Có | AI159: =IF((R159)>=6,"Có","Không") -> Có | AJ159: =IF(OR(J159>=140,K159>=90),"Có","Không") -> Có | AK159: ẤP BIỂN TÂY B, Phường Hiệp Thành, Tỉnh Cà Mau | AL159: 46081 | AM159: ="Tháng "&MONTH(AL159) -> Tháng 2 | AN159: =LEFT(AK159,FIND(",",AK159)-1) -> ẤP BIỂN TÂY B
A160: NGUYỄN VĂN DỞ | B160: Nam | C160: 01/01/1961 | D160: =DATEDIF(C160,TODAY(),"Y") -> 65 | E160: Có | F160: 170 | G160: 55 | H160: =G160/((F160/100)*(F160/100)) -> 19.031142 | I160: 76 | J160: 120 | K160: 80 | L160: =IF(B160="Nữ",0,2) -> 2 | M160: =IF(D160<45,0,IF(D160<=49,1,2)) -> 2 | N160: =IF(E160="Có",4,0) -> 4 | O160: =IF(H160<23,0,IF(H160<27.5,3,5)) -> 0 | P160: =IF(OR(AND(B160="Nam",I160>=90),AND(B160="Nữ",I160>=80)),2,0) -> 0 | Q160: =IF(OR(J160>=140,K160>=90),2,0) -> 0 | R160: =SUM(L160:Q160) -> 8 | AD160: x | AF160: =IF(COUNTIF(S160:Z160,"X")>=2,"Có","Không") -> Không | AG160: =IF(COUNTIF(AA160:AE160,"X")>=3,"Có","Không") -> Không | AH160: =IF((R160)>=6,"Có","Không") -> Có | AI160: =IF((R160)>=6,"Có","Không") -> Có | AJ160: =IF(OR(J160>=140,K160>=90),"Có","Không") -> Không | AK160: Khóm Giồng Giữa, Phường Hiệp Thành, Tỉnh Cà Mau | AL160: 46081 | AM160: ="Tháng "&MONTH(AL160) -> Tháng 2 | AN160: =LEFT(AK160,FIND(",",AK160)-1) -> Khóm Giồng Giữa
A161: LA THỊ HỒNG DÂN | B161: Nữ | C161: 01/01/1972 | D161: =DATEDIF(C161,TODAY(),"Y") -> 54 | E161: Không | F161: 164 | G161: 61 | H161: =G161/((F161/100)*(F161/100)) -> 22.679952 | I161: 90 | J161: 120 | K161: 80 | L161: =IF(B161="Nữ",0,2) -> 0 | M161: =IF(D161<45,0,IF(D161<=49,1,2)) -> 2 | N161: =IF(E161="Có",4,0) -> 0 | O161: =IF(H161<23,0,IF(H161<27.5,3,5)) -> 0 | P161: =IF(OR(AND(B161="Nam",I161>=90),AND(B161="Nữ",I161>=80)),2,0) -> 2 | Q161: =IF(OR(J161>=140,K161>=90),2,0) -> 0 | R161: =SUM(L161:Q161) -> 4 | AD161: x | AF161: =IF(COUNTIF(S161:Z161,"X")>=2,"Có","Không") -> Không | AG161: =IF(COUNTIF(AA161:AE161,"X")>=3,"Có","Không") -> Không | AH161: =IF((R161)>=6,"Có","Không") -> Không | AI161: =IF((R161)>=6,"Có","Không") -> Không | AJ161: =IF(OR(J161>=140,K161>=90),"Có","Không") -> Không | AK161: Xã Vĩnh Trạch Đông, Thành phố Bạc Liêu, Tỉnh Bạc Liêu | AL161: 46081 | AM161: ="Tháng "&MONTH(AL161) -> Tháng 2 | AN161: =LEFT(AK161,FIND(",",AK161)-1) -> Xã Vĩnh Trạch Đông
A162: TÁC VĂN HÚA | B162: Nam | C162: 01/01/1957 | D162: =DATEDIF(C162,TODAY(),"Y") -> 69 | E162: Không | F162: 167 | G162: 66 | H162: =G162/((F162/100)*(F162/100)) -> 23.665244 | I162: 91 | J162: 120 | K162: 80 | L162: =IF(B162="Nữ",0,2) -> 2 | M162: =IF(D162<45,0,IF(D162<=49,1,2)) -> 2 | N162: =IF(E162="Có",4,0) -> 0 | O162: =IF(H162<23,0,IF(H162<27.5,3,5)) -> 3 | P162: =IF(OR(AND(B162="Nam",I162>=90),AND(B162="Nữ",I162>=80)),2,0) -> 2 | Q162: =IF(OR(J162>=140,K162>=90),2,0) -> 0 | R162: =SUM(L162:Q162) -> 9 | AD162: x | AF162: =IF(COUNTIF(S162:Z162,"X")>=2,"Có","Không") -> Không | AG162: =IF(COUNTIF(AA162:AE162,"X")>=3,"Có","Không") -> Không | AH162: =IF((R162)>=6,"Có","Không") -> Có | AI162: =IF((R162)>=6,"Có","Không") -> Có | AJ162: =IF(OR(J162>=140,K162>=90),"Có","Không") -> Không | AK162: Ấp Giồng Giữa B, Phường Hiệp Thành, Tỉnh Cà Mau | AL162: 46081 | AM162: ="Tháng "&MONTH(AL162) -> Tháng 2 | AN162: =LEFT(AK162,FIND(",",AK162)-1) -> Ấp Giồng Giữa B
A163: LÊ MỘNG TIỀN | B163: Nữ | C163: 01/01/1977 | D163: =DATEDIF(C163,TODAY(),"Y") -> 49 | E163: Không | F163: 170 | G163: 60 | H163: =G163/((F163/100)*(F163/100)) -> 20.761246 | I163: 88 | J163: 120 | K163: 70 | L163: =IF(B163="Nữ",0,2) -> 0 | M163: =IF(D163<45,0,IF(D163<=49,1,2)) -> 1 | N163: =IF(E163="Có",4,0) -> 0 | O163: =IF(H163<23,0,IF(H163<27.5,3,5)) -> 0 | P163: =IF(OR(AND(B163="Nam",I163>=90),AND(B163="Nữ",I163>=80)),2,0) -> 2 | Q163: =IF(OR(J163>=140,K163>=90),2,0) -> 0 | R163: =SUM(L163:Q163) -> 3 | AD163: x | AF163: =IF(COUNTIF(S163:Z163,"X")>=2,"Có","Không") -> Không | AG163: =IF(COUNTIF(AA163:AE163,"X")>=3,"Có","Không") -> Không | AH163: =IF((R163)>=6,"Có","Không") -> Không | AI163: =IF((R163)>=6,"Có","Không") -> Không | AJ163: =IF(OR(J163>=140,K163>=90),"Có","Không") -> Không | AK163: Xóm Lẫm, Phường Hiệp Thành, Tỉnh Cà Mau | AL163: 46081 | AM163: ="Tháng "&MONTH(AL163) -> Tháng 2 | AN163: =LEFT(AK163,FIND(",",AK163)-1) -> Xóm Lẫm
A164: LÂM THỊ ÚT | B164: Nữ | C164: 01/01/1976 | D164: =DATEDIF(C164,TODAY(),"Y") -> 50 | E164: Không | F164: 158 | G164: 58 | H164: =G164/((F164/100)*(F164/100)) -> 23.233456 | I164: 72 | J164: 140 | K164: 80 | L164: =IF(B164="Nữ",0,2) -> 0 | M164: =IF(D164<45,0,IF(D164<=49,1,2)) -> 2 | N164: =IF(E164="Có",4,0) -> 0 | O164: =IF(H164<23,0,IF(H164<27.5,3,5)) -> 3 | P164: =IF(OR(AND(B164="Nam",I164>=90),AND(B164="Nữ",I164>=80)),2,0) -> 0 | Q164: =IF(OR(J164>=140,K164>=90),2,0) -> 2 | R164: =SUM(L164:Q164) -> 7 | AD164: x | AF164: =IF(COUNTIF(S164:Z164,"X")>=2,"Có","Không") -> Không | AG164: =IF(COUNTIF(AA164:AE164,"X")>=3,"Có","Không") -> Không | AH164: =IF((R164)>=6,"Có","Không") -> Có | AI164: =IF((R164)>=6,"Có","Không") -> Có | AJ164: =IF(OR(J164>=140,K164>=90),"Có","Không") -> Có | AK164: Biển Đông A, Phường Hiệp Thành, Tỉnh Cà Mau | AL164: 46081 | AM164: ="Tháng "&MONTH(AL164) -> Tháng 2 | AN164: =LEFT(AK164,FIND(",",AK164)-1) -> Biển Đông A
...

Sheet KSL TÍNH ĐẾN THÁNG 4
A1: Họ tên (*) | B1: Giới tính (*) | C1: Năm sinh (*) | D1: Tuổi | E1: Gia đình mắc ĐTD | F1: Chiều cao | G1: Cân nặng | H1: BMI | I1: Vòng eo | J1: HA tâm thu (*) | K1: HA tâm trương (*) | L1: Điểm Giới tính | M1: Điểm Tuổi | N1: Điểm Gia đình | O1: Điểm BMI | P1: Điểm Vòng eo | Q1: Điểm Huyết áp | R1: Tổng điểm | S1: Cần xét nghiệm đường máu mao mạch | T1: Nguy cơ Đái tháo đường | U1: Nghi ngờ Tăng huyết áp | V1: Địa chỉ | W1: Ngày khám (*) | X1: Tháng | Y1: Khóm
A2: LIÊU THỊ NHE | B2: Nữ | C2: 01/01/1943 | D2: =DATEDIF(C2,TODAY(),"Y") -> 83 | E2: Có | F2: 161 | G2: 68 | H2: =G2/((F2/100)*(F2/100)) -> 26.233556 | I2: 89 | J2: 120 | K2: 80 | L2: =IF(B2="Nữ",0,2) -> 0 | M2: =IF(D2<45,0,IF(D2<=49,1,2)) -> 2 | N2: =IF(E2="Có",4,0) -> 4 | O2: =IF(H2<23,0,IF(H2<27.5,3,5)) -> 3 | P2: =IF(OR(AND(B2="Nam",I2>=90),AND(B2="Nữ",I2>=80)),2,0) -> 2 | Q2: =IF(OR(J2>=140,K2>=90),2,0) -> 0 | R2: =SUM(L2:Q2) -> 11 | S2: =IF((R2)>=6,"Có","Không cần") -> Có | T2: =IF((R2)>=6,"Có","Không") -> Có | U2: =IF(OR(J2>=140,K2>=90),"Có","Không") -> Không | V2: Ấp Biển Đông A, Phường Hiệp Thành, Tỉnh Cà Mau | W2: 46142 | X2: ="Tháng "&MONTH(W2) -> Tháng 4 | Y2: =LEFT(V2,FIND(",",V2)-1) -> Ấp Biển Đông A
A3: QUÁCH XÔM | B3: Nam | C3: 01/01/1947 | D3: =DATEDIF(C3,TODAY(),"Y") -> 79 | E3: Không | F3: 170 | G3: 75 | H3: =G3/((F3/100)*(F3/100)) -> 25.951557 | I3: 81 | J3: 120 | K3: 80 | L3: =IF(B3="Nữ",0,2) -> 2 | M3: =IF(D3<45,0,IF(D3<=49,1,2)) -> 2 | N3: =IF(E3="Có",4,0) -> 0 | O3: =IF(H3<23,0,IF(H3<27.5,3,5)) -> 3 | P3: =IF(OR(AND(B3="Nam",I3>=90),AND(B3="Nữ",I3>=80)),2,0) -> 0 | Q3: =IF(OR(J3>=140,K3>=90),2,0) -> 0 | R3: =SUM(L3:Q3) -> 7 | S3: =IF((R3)>=6,"Có","Không cần") -> Có | T3: =IF((R3)>=6,"Có","Không") -> Có | U3: =IF(OR(J3>=140,K3>=90),"Có","Không") -> Không | V3: Ấp Giồng Giữa B, Phường Hiệp Thành, Tỉnh Cà Mau | W3: 46142 | X3: ="Tháng "&MONTH(W3) -> Tháng 4 | Y3: =LEFT(V3,FIND(",",V3)-1) -> Ấp Giồng Giữa B
A4: HUỲNH VĂN HAI | B4: Nam | C4: 01/01/1948 | D4: =DATEDIF(C4,TODAY(),"Y") -> 78 | E4: Có | F4: 172 | G4: 65 | H4: =G4/((F4/100)*(F4/100)) -> 21.971336 | I4: 83 | J4: 130 | K4: 80 | L4: =IF(B4="Nữ",0,2) -> 2 | M4: =IF(D4<45,0,IF(D4<=49,1,2)) -> 2 | N4: =IF(E4="Có",4,0) -> 4 | O4: =IF(H4<23,0,IF(H4<27.5,3,5)) -> 0 | P4: =IF(OR(AND(B4="Nam",I4>=90),AND(B4="Nữ",I4>=80)),2,0) -> 0 | Q4: =IF(OR(J4>=140,K4>=90),2,0) -> 0 | R4: =SUM(L4:Q4) -> 8 | S4: =IF((R4)>=6,"Có","Không cần") -> Có | T4: =IF((R4)>=6,"Có","Không") -> Có | U4: =IF(OR(J4>=140,K4>=90),"Có","Không") -> Không | V4: Chòm Xoài, Phường Hiệp Thành, Tỉnh Cà Mau | W4: 46142 | X4: ="Tháng "&MONTH(W4) -> Tháng 4 | Y4: =LEFT(V4,FIND(",",V4)-1) -> Chòm Xoài
A5: THẠCH CƯƠNG | B5: Nam | C5: 01/01/1951 | D5: =DATEDIF(C5,TODAY(),"Y") -> 75 | E5: Không | F5: 169 | G5: 68 | H5: =G5/((F5/100)*(F5/100)) -> 23.80869 | I5: 81 | J5: 120 | K5: 80 | L5: =IF(B5="Nữ",0,2) -> 2 | M5: =IF(D5<45,0,IF(D5<=49,1,2)) -> 2 | N5: =IF(E5="Có",4,0) -> 0 | O5: =IF(H5<23,0,IF(H5<27.5,3,5)) -> 3 | P5: =IF(OR(AND(B5="Nam",I5>=90),AND(B5="Nữ",I5>=80)),2,0) -> 0 | Q5: =IF(OR(J5>=140,K5>=90),2,0) -> 0 | R5: =SUM(L5:Q5) -> 7 | S5: =IF((R5)>=6,"Có","Không cần") -> Có | T5: =IF((R5)>=6,"Có","Không") -> Có | U5: =IF(OR(J5>=140,K5>=90),"Có","Không") -> Không | V5: Ấp Biển Đông B, Phường Hiệp Thành, Tỉnh Cà Mau | W5: 46142 | X5: ="Tháng "&MONTH(W5) -> Tháng 4 | Y5: =LEFT(V5,FIND(",",V5)-1) -> Ấp Biển Đông B
A6: TRẦN THỊ SÀ MÂY | B6: Nữ | C6: 01/01/1956 | D6: =DATEDIF(C6,TODAY(),"Y") -> 70 | E6: Có | F6: 168 | G6: 68 | H6: =G6/((F6/100)*(F6/100)) -> 24.092971 | I6: 80 | J6: 150 | K6: 80 | L6: =IF(B6="Nữ",0,2) -> 0 | M6: =IF(D6<45,0,IF(D6<=49,1,2)) -> 2 | N6: =IF(E6="Có",4,0) -> 4 | O6: =IF(H6<23,0,IF(H6<27.5,3,5)) -> 3 | P6: =IF(OR(AND(B6="Nam",I6>=90),AND(B6="Nữ",I6>=80)),2,0) -> 2 | Q6: =IF(OR(J6>=140,K6>=90),2,0) -> 2 | R6: =SUM(L6:Q6) -> 13 | S6: =IF((R6)>=6,"Có","Không cần") -> Có | T6: =IF((R6)>=6,"Có","Không") -> Có | U6: =IF(OR(J6>=140,K6>=90),"Có","Không") -> Có | V6: Ấp Biển Đông A, Phường Hiệp Thành, Tỉnh Cà Mau | W6: 46142 | X6: ="Tháng "&MONTH(W6) -> Tháng 4 | Y6: =LEFT(V6,FIND(",",V6)-1) -> Ấp Biển Đông A
A7: DƯƠNG THỊ MAI | B7: Nữ | C7: 01/01/1967 | D7: =DATEDIF(C7,TODAY(),"Y") -> 59 | E7: Không | F7: 167 | G7: 60 | H7: =G7/((F7/100)*(F7/100)) -> 21.513859 | I7: 76 | J7: 120 | K7: 80 | L7: =IF(B7="Nữ",0,2) -> 0 | M7: =IF(D7<45,0,IF(D7<=49,1,2)) -> 2 | N7: =IF(E7="Có",4,0) -> 0 | O7: =IF(H7<23,0,IF(H7<27.5,3,5)) -> 0 | P7: =IF(OR(AND(B7="Nam",I7>=90),AND(B7="Nữ",I7>=80)),2,0) -> 0 | Q7: =IF(OR(J7>=140,K7>=90),2,0) -> 0 | R7: =SUM(L7:Q7) -> 2 | S7: =IF((R7)>=6,"Có","Không cần") -> Không cần | T7: =IF((R7)>=6,"Có","Không") -> Không | U7: =IF(OR(J7>=140,K7>=90),"Có","Không") -> Không | V7: Ấp Giồng Nhãn A, Phường Hiệp Thành, Tỉnh Cà Mau | W7: 46142 | X7: ="Tháng "&MONTH(W7) -> Tháng 4 | Y7: =LEFT(V7,FIND(",",V7)-1) -> Ấp Giồng Nhãn A
A8: THẠCH THỊ NƯƠNG | B8: Nữ | C8: 01/01/1976 | D8: =DATEDIF(C8,TODAY(),"Y") -> 50 | E8: Không | F8: 168 | G8: 68 | H8: =G8/((F8/100)*(F8/100)) -> 24.092971 | I8: 86 | J8: 130 | K8: 80 | L8: =IF(B8="Nữ",0,2) -> 0 | M8: =IF(D8<45,0,IF(D8<=49,1,2)) -> 2 | N8: =IF(E8="Có",4,0) -> 0 | O8: =IF(H8<23,0,IF(H8<27.5,3,5)) -> 3 | P8: =IF(OR(AND(B8="Nam",I8>=90),AND(B8="Nữ",I8>=80)),2,0) -> 2 | Q8: =IF(OR(J8>=140,K8>=90),2,0) -> 0 | R8: =SUM(L8:Q8) -> 7 | S8: =IF((R8)>=6,"Có","Không cần") -> Có | T8: =IF((R8)>=6,"Có","Không") -> Có | U8: =IF(OR(J8>=140,K8>=90),"Có","Không") -> Không | V8: Ấp Biển Đông B, Phường Hiệp Thành, Tỉnh Cà Mau | W8: 46142 | X8: ="Tháng "&MONTH(W8) -> Tháng 4 | Y8: =LEFT(V8,FIND(",",V8)-1) -> Ấp Biển Đông B
A9: ĐINH THỊ LANG | B9: Nữ | C9: 01/01/1971 | D9: =DATEDIF(C9,TODAY(),"Y") -> 55 | E9: Không | F9: 168 | G9: 68 | H9: =G9/((F9/100)*(F9/100)) -> 24.092971 | I9: 71 | J9: 120 | K9: 80 | L9: =IF(B9="Nữ",0,2) -> 0 | M9: =IF(D9<45,0,IF(D9<=49,1,2)) -> 2 | N9: =IF(E9="Có",4,0) -> 0 | O9: =IF(H9<23,0,IF(H9<27.5,3,5)) -> 3 | P9: =IF(OR(AND(B9="Nam",I9>=90),AND(B9="Nữ",I9>=80)),2,0) -> 0 | Q9: =IF(OR(J9>=140,K9>=90),2,0) -> 0 | R9: =SUM(L9:Q9) -> 5 | S9: =IF((R9)>=6,"Có","Không cần") -> Không cần | T9: =IF((R9)>=6,"Có","Không") -> Không | U9: =IF(OR(J9>=140,K9>=90),"Có","Không") -> Không | V9: ấp Giồng Giữa A, Phường Hiệp Thành, Tỉnh Cà Mau | W9: 46142 | X9: ="Tháng "&MONTH(W9) -> Tháng 4 | Y9: =LEFT(V9,FIND(",",V9)-1) -> ấp Giồng Giữa A
A10: QUÁCH THANH HẢI | B10: Nam | C10: 01/01/1968 | D10: =DATEDIF(C10,TODAY(),"Y") -> 58 | E10: Có | F10: 170 | G10: 75 | H10: =G10/((F10/100)*(F10/100)) -> 25.951557 | I10: 87 | J10: 120 | K10: 80 | L10: =IF(B10="Nữ",0,2) -> 2 | M10: =IF(D10<45,0,IF(D10<=49,1,2)) -> 2 | N10: =IF(E10="Có",4,0) -> 4 | O10: =IF(H10<23,0,IF(H10<27.5,3,5)) -> 3 | P10: =IF(OR(AND(B10="Nam",I10>=90),AND(B10="Nữ",I10>=80)),2,0) -> 0 | Q10: =IF(OR(J10>=140,K10>=90),2,0) -> 0 | R10: =SUM(L10:Q10) -> 11 | S10: =IF((R10)>=6,"Có","Không cần") -> Có | T10: =IF((R10)>=6,"Có","Không") -> Có | U10: =IF(OR(J10>=140,K10>=90),"Có","Không") -> Không | V10: Phường Hiệp Thành, Tỉnh Cà Mau | W10: 46142 | X10: ="Tháng "&MONTH(W10) -> Tháng 4 | Y10: =LEFT(V10,FIND(",",V10)-1) -> Phường Hiệp Thành
A11: LÝ THỊ BỮU HUA | B11: Nữ | C11: 01/01/1954 | D11: =DATEDIF(C11,TODAY(),"Y") -> 72 | E11: Không | F11: 158 | G11: 58 | H11: =G11/((F11/100)*(F11/100)) -> 23.233456 | I11: 65 | J11: 120 | K11: 80 | L11: =IF(B11="Nữ",0,2) -> 0 | M11: =IF(D11<45,0,IF(D11<=49,1,2)) -> 2 | N11: =IF(E11="Có",4,0) -> 0 | O11: =IF(H11<23,0,IF(H11<27.5,3,5)) -> 3 | P11: =IF(OR(AND(B11="Nam",I11>=90),AND(B11="Nữ",I11>=80)),2,0) -> 0 | Q11: =IF(OR(J11>=140,K11>=90),2,0) -> 0 | R11: =SUM(L11:Q11) -> 5 | S11: =IF((R11)>=6,"Có","Không cần") -> Không cần | T11: =IF((R11)>=6,"Có","Không") -> Không | U11: =IF(OR(J11>=140,K11>=90),"Có","Không") -> Không | V11: Khóm 3, Phường Bạc Liêu, Tỉnh Cà Mau | W11: 46142 | X11: ="Tháng "&MONTH(W11) -> Tháng 4 | Y11: =LEFT(V11,FIND(",",V11)-1) -> Khóm 3
A12: NGUYỄN THỊ DUYÊN | B12: Nữ | C12: 01/01/1961 | D12: =DATEDIF(C12,TODAY(),"Y") -> 65 | E12: Không | F12: 160 | G12: 63 | H12: =G12/((F12/100)*(F12/100)) -> 24.609375 | I12: 75 | J12: 140 | K12: 80 | L12: =IF(B12="Nữ",0,2) -> 0 | M12: =IF(D12<45,0,IF(D12<=49,1,2)) -> 2 | N12: =IF(E12="Có",4,0) -> 0 | O12: =IF(H12<23,0,IF(H12<27.5,3,5)) -> 3 | P12: =IF(OR(AND(B12="Nam",I12>=90),AND(B12="Nữ",I12>=80)),2,0) -> 0 | Q12: =IF(OR(J12>=140,K12>=90),2,0) -> 2 | R12: =SUM(L12:Q12) -> 7 | S12: =IF((R12)>=6,"Có","Không cần") -> Có | T12: =IF((R12)>=6,"Có","Không") -> Có | U12: =IF(OR(J12>=140,K12>=90),"Có","Không") -> Có | V12: xã hiệp thành, Phường Hiệp Thành, Tỉnh Cà Mau | W12: 46142 | X12: ="Tháng "&MONTH(W12) -> Tháng 4 | Y12: =LEFT(V12,FIND(",",V12)-1) -> xã hiệp thành
A13: LÂM THỊ SANG | B13: Nữ | C13: 01/01/1952 | D13: =DATEDIF(C13,TODAY(),"Y") -> 74 | E13: Không | F13: 168 | G13: 68 | H13: =G13/((F13/100)*(F13/100)) -> 24.092971 | I13: 72 | J13: 140 | K13: 80 | L13: =IF(B13="Nữ",0,2) -> 0 | M13: =IF(D13<45,0,IF(D13<=49,1,2)) -> 2 | N13: =IF(E13="Có",4,0) -> 0 | O13: =IF(H13<23,0,IF(H13<27.5,3,5)) -> 3 | P13: =IF(OR(AND(B13="Nam",I13>=90),AND(B13="Nữ",I13>=80)),2,0) -> 0 | Q13: =IF(OR(J13>=140,K13>=90),2,0) -> 2 | R13: =SUM(L13:Q13) -> 7 | S13: =IF((R13)>=6,"Có","Không cần") -> Có | T13: =IF((R13)>=6,"Có","Không") -> Có | U13: =IF(OR(J13>=140,K13>=90),"Có","Không") -> Có | V13: ấp Biển Đông A, Phường Hiệp Thành, Tỉnh Cà Mau | W13: 46142 | X13: ="Tháng "&MONTH(W13) -> Tháng 4 | Y13: =LEFT(V13,FIND(",",V13)-1) -> ấp Biển Đông A
... A30: THẠCH HEL | B30: Nữ | C30: 01/01/1934 | D30: =DATEDIF(C30,TODAY(),"Y") -> 92 | E30: Không | F30: 169 | G30: 68 | H30: =G30/((F30/100)*(F30/100)) -> 23.80869 | I30: 79 | J30: 120 | K30: 80 | L30: =IF(B30="Nữ",0,2) -> 0 | M30: =IF(D30<45,0,IF(D30<=49,1,2)) -> 2 | N30: =IF(E30="Có",4,0) -> 0 | O30: =IF(H30<23,0,IF(H30<27.5,3,5)) -> 3 | P30: =IF(OR(AND(B30="Nam",I30>=90),AND(B30="Nữ",I30>=80)),2,0) -> 0 | Q30: =IF(OR(J30>=140,K30>=90),2,0) -> 0 | R30: =SUM(L30:Q30) -> 5 | S30: =IF((R30)>=6,"Có","Không cần") -> Không cần | T30: =IF((R30)>=6,"Có","Không") -> Không | U30: =IF(OR(J30>=140,K30>=90),"Có","Không") -> Không | V30: Phường Hiệp Thành, Tỉnh Cà Mau | W30: 46142 | X30: ="Tháng "&MONTH(W30) -> Tháng 4 | Y30: =LEFT(V30,FIND(",",V30)-1) -> Phường Hiệp Thành
A31: THACH CƯƠNG | B31: Nam | C31: 01/01/1957 | D31: =DATEDIF(C31,TODAY(),"Y") -> 69 | E31: Không | F31: 166 | G31: 58 | H31: =G31/((F31/100)*(F31/100)) -> 21.048048 | I31: 89 | J31: 120 | K31: 80 | L31: =IF(B31="Nữ",0,2) -> 2 | M31: =IF(D31<45,0,IF(D31<=49,1,2)) -> 2 | N31: =IF(E31="Có",4,0) -> 0 | O31: =IF(H31<23,0,IF(H31<27.5,3,5)) -> 0 | P31: =IF(OR(AND(B31="Nam",I31>=90),AND(B31="Nữ",I31>=80)),2,0) -> 0 | Q31: =IF(OR(J31>=140,K31>=90),2,0) -> 0 | R31: =SUM(L31:Q31) -> 4 | S31: =IF((R31)>=6,"Có","Không cần") -> Không cần | T31: =IF((R31)>=6,"Có","Không") -> Không | U31: =IF(OR(J31>=140,K31>=90),"Có","Không") -> Không | V31: ấp Biển tây B, Phường Hiệp Thành, Tỉnh Cà Mau | W31: 09/03/2026 | X31: ="Tháng "&MONTH(W31) -> Tháng 3 | Y31: =LEFT(V31,FIND(",",V31)-1) -> ấp Biển tây B
